Workbook
Name Index: #REF!
Name Index: '[1]Term Dump'!$B$3:$B$38
Name Index: '[1]Term Dump'!$B$3:$B$38
Name Index: '[2]Term Dump'!$B$3:$B$38
Name Index: '[3]Term Dump'!$B$3:$B$38
Name Index: '[4]Term Dump'!$B$3:$B$38
Name Index: #REF!
Name Index: #REF!
Name Index: #REF!
Name Transaction: #REF!
Name Transaction: '[1]Term Dump'!$C$3:$C$8
Name Transaction: '[1]Term Dump'!$C$3:$C$8
Name Transaction: '[2]Term Dump'!$C$3:$C$8
Name Transaction: '[3]Term Dump'!$C$3:$C$8
Name Transaction: '[4]Term Dump'!$C$3:$C$8
Name Transaction: #REF!
Name Transaction: #REF!
Name Transaction: #REF!

Sheet Portfolio Allocation
B1: from Live consol | D1: 3 | E1: 12.085 | F1: 41.5 | G1: 0.032 | H1: =IFERROR(G1/$G$5,0) -> 0.042299592 | J1: 9 | L1: =N1 -> 38.415 | N1: =(F1+J1)-E1 -> 38.415 | P1: 15 | Q1: 16 | S1: 18 | T1: 19
B2: Category | D2: Investment Date Range | E2: Investment at Cost | F2: Market Value | G2: Allocation (%) | H2: Allocation (% of Asset Class) | J2: Dividend / Interest | L2: Absolute Gain / (Loss) Including Redeemed Funds | N2: Absolute Gain / (Loss) Active Funds | P2: Absolute Returns (%) | S2: Annualized Returns (%)
C3: S | P3: Portfolio | Q3: Blended Index | S3: Portfolio | T3: Blended Index
B4: Equity | E4: =SUM(E7:E15) -> 810.70047 | F4: =SUM(F7:F15) -> 1024.9989 | G4: =SUM(G7:G15) -> 0.78843032 | H4: =SUM(H7:H15) -> 1 | J4: =SUM(J7:J14) -> 1.8432324 | L4: =SUM(L7:L15) -> 20734.548 | N4: =SUM(N7:N15) -> 216.14357 | P4: 0.26003127 | Q4: 0.049233916 | S4: 0.22988721 | T4: 0.051674172
B5: Equity (Excl NSE) | E5: =E4-E1 -> 798.61547 | F5: =F4-F1 -> 983.49886 | G5: =F5/F28 -> 0.75650847 | H5: =F5/F4 -> 0.95951215 | J5: 1.8432324 | L5: 20705.133 | N5: 186.72857 | P5: 0.1924727 | Q5: 0.041027379 | S5: 0.19345655 | T5: 0.048554507
B6: Equity (Excl NSE / External Direct Equity) | E6: =E5-E9 -> 648.20141 | F6: =F5-F9 -> 761.14021 | G6: =F6/F28 -> 0.58546994 | H6: =F6/F4 -> 0.74257664 | L6: =L5-L9 -> 13817.752 | N6: =N5-N9 -> 112.95665 | P6: =P29 -> 0.1458522 | Q6: =Q29 -> 0.035615199 | S6: =S29 -> 0.15754278 | T6: =T29 -> 0.042163882
B7: Direct Equity - MO | D7: Nov-22 - Dec-25 | E7: 17.731316 | F7: 21.640258 | G7: =F7/$F$28 -> 0.016645712 | H7: =F7/$F$4 -> 0.02111247 | J7: 0 | L7: 682.89959 | N7: 3.9089419 | P7: 0.26617787 | Q7: 0.055932598 | S7: 0.17558801 | T7: 0.038443562
B8: Direct Equity - Unlisted | D8: Dec-22 - Feb-25 | E8: 27.086596 | F8: 64.328516 | G8: =F8/$F$28 -> 0.04948157 | H8: =F8/$F$4 -> 0.062759597 | J8: 0 | L8: 3724.192 | N8: 37.24192 | P8: 1.3749206 | Q8: 0.29941829 | S8: 0.5395584 | T8: 0.15761568
B9: Direct Equity - Non MO | D9: Jul-23 - Jun-26 | E9: 150.41406 | F9: 222.35865 | G9: =F9/$F$28 -> 0.17103853 | H9: =F9/$F$4 -> 0.21693551 | J9: 1.8273252 | L9: 6887.3804 | N9: 73.771919 | P9: 0.43578585 | Q9: 0.069273635 | S9: 0.32026554 | T9: 0.072169986
B10: Multi Cap | D10: March 20 - Aug 25 | E10: 332.69671 | F10: 361.70793 | G10: =F10/$F$28 -> 0.27822617 | H10: =F10/$F$4 -> 0.35288618 | J10: 0 | L10: 2945.7612 | N10: 29.011228 | P10: 0.087685415 | Q10: 0.024078156 | S10: 0.093634906 | T10: 0.026127818
B11: Equity Hybrid | D11: May-22 - Jan-26 | E11: 96.675688 | F11: 105.98628 | G11: =F11/$F$28 -> 0.081524771 | H11: =F11/$F$4 -> 0.10340136 | J11: 0 | L11: 188.74821 | N11: 9.310592 | P11: 0.10094745 | Q11: 0.038213701 | S11: 0.016414568 | T11: 0.034314373
B12: Mid & Small Cap | D12: Sep-24 - Dec-25 | E12: 183.99973 | F12: 246.75783 | G12: =F12/$F$28 -> 0.18980641 | H12: =F12/$F$4 -> 0.24073962 | J12: 0.015907185 | L12: 6277.4015 | N12: 62.774015 | P12: 0.34116363 | Q12: 0.045401409 | S12: 0.4334171 | T12: 0.056590232
B13: Small Cap | D13: Oct-24 - Oct-24 | E13: 1 | F13: 1.1248249 | G13: =F13/$F$28 -> 0.00086521663 | H13: =F13/$F$4 -> 0.0010973914 | J13: 0 | L13: 12.48249 | N13: 0.1248249 | P13: 0.1248249 | Q13: 0.018808085 | S13: 0.072427824 | T13: 0.011138436
B14: SLBM | E14: 0 | F14: 0.24478595 | G14: =F14/$F$28 -> 0.00018828964 | H14: =F14/$F$4 -> 0.00023881583 | J14: 0 | L14: 24.478595 | N14: 0.24478595
B15: LKP Sec Portfolio | D15: Mar-25 - May-26 | E15: 1.0963805 | F15: 0.84977725 | G15: =F15/$F$28 -> 0.00065364966 | H15: =F15/$F$4 -> 0.0008290519 | J15: 0.00195 | L15: -8.7961095 | N15: -0.24465325 | P15: -0.072034374 | Q15: 0.069722837 | S15: -0.10054799 | T15: 0.09777804
B16: Debt | E16: =SUM(E17:E19) -> 43.954001 | F16: =SUM(F17:F19) -> 45.889164 | G16: =SUM(G17:G19) -> 0.035297998 | H16: 1 | J16: =SUM(J17:J19) -> 0.3592938 | L16: =SUM(L17:L19) -> 455.9288 | N16: =SUM(N17:N19) -> 2.2944563 | P16: 0.044904795 | Q16: 0.040250698 | S16: 0.081715778 | T16: 0.072796813
B17: High Yield Fund | D17: Oct-23 - Feb-26 | E17: 3.5 | F17: 3.768427 | G17: =F17/$F$28 -> 0.0028986784 | H17: =F17/$F$16 -> 0.082120193 | J17: 0.3592938 | L17: 76.934878 | N17: 0.62772078 | P17: 0.21981394 | Q17: 0.10395107 | S17: 0.14966583 | T17: 0.069996265
B18: PP Structures | D18: Sep-20 - Mar-24 | E18: 0.70001498 | F18: 1.0434584 | G18: =F18/$F$28 -> 0.00080262946 | H18: =F18/$F$16 -> 0.022738668 | J18: 0 | L18: 34.344347 | N18: 0.34344347 | P18: 0.49062302 | Q18: 0.24620557 | S18: 0.12367324 | T18: 0.067806676
B19: Arbitrage | D19: May-25 - May-26 | E19: 39.753986 | F19: 41.077278 | G19: =F19/$F$28 -> 0.031596691 | H19: =F19/$F$16 -> 0.89514114 | J19: 0 | L19: 344.64957 | N19: 1.3232921 | P19: 0.035409577 | Q19: 0.036478848 | S19: 0.07125822 | T19: 0.073410103
B20: Cash | E20: =E21 -> 5.1332383 | F20: =F21 -> 5.4365436 | G20: =G21 -> 0.0041817957 | H20: 1 | J20: =J21 -> 0 | L20: =L21 -> 34.79289 | N20: =N21 -> 0.30330523 | P20: 0.021945572 | Q20: 0.027548659 | S20: 0.042472556 | T20: 0.053490874
B21: Liquid | D21: Jul-19 - Jun-26 | E21: 5.1332383 | F21: 5.4365436 | G21: =F21/$F$28 -> 0.0041817957 | H21: =F21/$F$20 -> 1 | J21: 0 | L21: 34.79289 | N21: 0.30330523 | P21: 0.021945572 | Q21: 0.027548659 | S21: 0.042472556 | T21: 0.053490874
B22: Alternate | E22: =SUM(E23:E26) -> 216.22516 | F22: =SUM(F23:F26) -> 223.72546 | G22: =SUM(G23:G26) -> 0.17208988 | H22: =SUM(H23:H26) -> 1 | J22: =SUM(J23:J26) -> 0.4347699 | L22: =SUM(L23:L26) -> 505.32827 | N22: =SUM(N23:N26) -> 7.9350638 | P22: 0.055646167 | Q22: 0.03088796 | S22: 0.091461167 | T22: 0.050356653
B23: Silver | D23: Sept'25-Jan'26 | E23: 4.2561917 | F23: 6.5449619 | G23: =F23/$F$28 -> 0.0050343924 | H23: =F23/$F$22 -> 0.029254435 | J23: 0 | L23: 616.02738 | N23: 2.2887702 | P23: 0.74830014 | Q23: 0.82390612
B24: Gold | D24: Jan-26 - Jan-26 | E24: 53.585434 | F24: 48.307867 | G24: =F24/$F$28 -> 0.037158468 | H24: =F24/$F$22 -> 0.21592476 | J24: 0 | L24: -527.7567 | N24: -5.277567 | P24: -0.098488836 | Q24: -0.091201257
B25: PE Funds | D25: Apr-21 - Mar-26 | E25: 22.224236 | F25: 32.713327 | G25: =F25/$F$28 -> 0.025163129 | H25: =F25/$F$22 -> 0.14622085 | J25: 0.4347699 | L25: 417.05758 | N25: 10.923861 | P25: 0.14384676 | Q25: 0.031363764 | S25: 0.13349357 | T25: 0.030562511
B26: Private Equity | D26: Nov 12 - Sept 24 | E26: 136.1593 | F26: 136.1593 | G26: =F26/$F$28 -> 0.1047339 | H26: =F26/$F$22 -> 0.60859995 | J26: 0 | L26: 0 | N26: 0
B28: Total | E28: =E22+E20+E16+E4 -> 1076.0129 | F28: =F22+F20+F16+F4 -> 1300.05 | G28: =G4+G16+G20+G22 -> 1 | J28: =J4+J16+J20+J22 -> 2.6372961 | L28: =L4+L16+L20+L22 -> 21730.598 | N28: =N4+N16+N20+N22 -> 226.6764 | P28: 0.21815232 | Q28: 0.046464029 | S28: 0.21178462 | T28: 0.0528
B29: Total Excl. External Direct Equity / NSE | E29: 925.59881 | F29: 1077.6914 | G29: =G4+G16+G20+G22-G9 -> 0.82896147 | J29: 0.8 | L29: 14843.217 | N29: 152.90448 | P29: 0.1458522 | Q29: 0.035615199 | S29: 0.15754278 | T29: 0.042163882
B30: Note: For investments less than one year, absolute returns have been shown. Private equity is shown at cost.

Sheet Promoter Holding
B7: Product | C7: Quantity | D7: Market Value in lacs
A8: 542652 | B8: Polycab India Ltd. | C8: =SUM(C11:C16) -> 23729601 | D8: =(C8*E8)/10^5 -> 0
B9: Total | C9: =SUM(C8:C8) -> 23729601 | D9: =SUM(D8:D8) -> 0
B11: Ajay JS: Individual | C11: 13901229 | D11: =(C11*$E$8)/10^5 -> 0 | E11: Source: ICIC Demat
B12: Category : Others | C12: 1300100 | D12: =(C12*$E$8)/10^5 -> 0 | E12: Source: Investor release (March 25)
B13: Category : Others | C13: 1100100 | D13: =(C13*$E$8)/10^5 -> 0 | E13: Source: Investor release (March 25)
B14: Category : Others | C14: 2150100 | D14: =(C14*$E$8)/10^5 -> 0 | E14: Source: Investor release (March 25)
B15: Aarti Ajay JS | C15: =62500-7000 -> 55500 | E15: Source: ICICI Demat as on 29th August 2025
B16: Bahart JS | C16: 5222572 | D16: =(C16*$E$8)/10^5 -> 0 | E16: Source: Investor release (March 25)

Sheet Live Equity Performance
B1: From Equity Live file | E1: Check | F1: =F4-'Portfolio Allocation'!F4 -> 0
B2: Category | D2: Investment Date Range | E2: Investment at Cost | F2: Market Value | G2: Allocation (%) | H2: Allocation (% of Asset Class) | J2: Dividend / Interest | L2: Absolute Gain / (Loss) Including Redeemed Funds | N2: Absolute Gain / (Loss) Active Funds | P2: Absolute Returns (%) | S2: Annualized Returns (%)
P3: Portfolio | Q3: Blended Index | S3: Portfolio | T3: Blended Index
B4: Equity | E4: =SUM(E7:E15) -> 810.70047 | F4: =SUM(F7:F15) -> 1024.9989 | G4: =IFERROR(F4/$F$16,0) -> 1 | H4: =SUM(H7:H15) -> 1 | J4: =SUM(J7:J15) -> 1.8451824 | L4: =SUM(L7:L15) -> 20734.548 | N4: =SUM(N7:N15) -> 216.14357 | P4: =VLOOKUP($B4,'Portfolio Allocation'!$B$2:$T$29,15,0) -> 0.26003127 | Q4: =VLOOKUP($B4,'Portfolio Allocation'!$B$2:$T$29,16,0) -> 0.049233916 | S4: =VLOOKUP($B4,'Portfolio Allocation'!$B$2:$T$29,18,0) -> 0.22988721 | T4: =VLOOKUP($B4,'Portfolio Allocation'!$B$2:$T$29,19,0) -> 0.051674172
B5: Equity (Excl NSE) | E5: ='Portfolio Allocation'!E5 -> 798.61547 | F5: ='Portfolio Allocation'!F5 -> 983.49886 | J5: ='Portfolio Allocation'!J5 -> 1.8432324 | L5: =L4-L8 -> 17010.356 | N5: =N4-N8 -> 178.90165 | P5: =VLOOKUP($B5,'Portfolio Allocation'!$B$2:$T$29,15,0) -> 0.1924727 | Q5: =VLOOKUP($B5,'Portfolio Allocation'!$B$2:$T$29,16,0) -> 0.041027379 | S5: =VLOOKUP($B5,'Portfolio Allocation'!$B$2:$T$29,18,0) -> 0.19345655 | T5: =VLOOKUP($B5,'Portfolio Allocation'!$B$2:$T$29,19,0) -> 0.048554507
B6: Equity (Excl NSE / External Direct Equity) | E6: =E5-E9 -> 648.20141 | F6: =F5-F9 -> 761.14021 | L6: =L5-L9 -> 10122.975 | N6: =N5-N9 -> 105.12973 | P6: =VLOOKUP($B6,'Portfolio Allocation'!$B$2:$T$29,15,0) -> 0.1458522 | Q6: =VLOOKUP($B6,'Portfolio Allocation'!$B$2:$T$29,16,0) -> 0.035615199 | S6: =VLOOKUP($B6,'Portfolio Allocation'!$B$2:$T$29,18,0) -> 0.15754278 | T6: =VLOOKUP($B6,'Portfolio Allocation'!$B$2:$T$29,19,0) -> 0.042163882
A7: * | B7: Direct Equity - MO | D7: ='Portfolio Allocation'!D7 -> Nov-22 - Dec-25 | E7: =VLOOKUP($B7,'Portfolio Allocation'!$B$2:$T$29,4,0) -> 17.731316 | F7: =VLOOKUP($B7,'Portfolio Allocation'!$B$2:$T$29,5,0) -> 21.640258 | G7: =IFERROR(F7/$F$16,0) -> 0.02111247 | H7: =IFERROR(G7/$G$4,0) -> 0.02111247 | J7: =VLOOKUP($B7,'Portfolio Allocation'!$B$2:$T$29,9,0) -> 0 | L7: ='Portfolio Allocation'!L7 -> 682.89959 | N7: =(F7+J7)-E7 -> 3.9089419 | P7: =VLOOKUP($B7,'Portfolio Allocation'!$B$2:$T$29,15,0) -> 0.26617787 | Q7: =VLOOKUP($B7,'Portfolio Allocation'!$B$2:$T$29,16,0) -> 0.055932598 | S7: =VLOOKUP($B7,'Portfolio Allocation'!$B$2:$T$29,18,0) -> 0.17558801 | T7: =VLOOKUP($B7,'Portfolio Allocation'!$B$2:$T$29,19,0) -> 0.038443562
B8: Direct Equity - Unlisted | D8: ='Portfolio Allocation'!D8 -> Dec-22 - Feb-25 | E8: =VLOOKUP($B8,'Portfolio Allocation'!$B$2:$T$29,4,0) -> 27.086596 | F8: =VLOOKUP($B8,'Portfolio Allocation'!$B$2:$T$29,5,0) -> 64.328516 | G8: =IFERROR(F8/$F$16,0) -> 0.062759597 | H8: =IFERROR(G8/$G$4,0) -> 0.062759597 | J8: =VLOOKUP($B8,'Portfolio Allocation'!$B$2:$T$29,9,0) -> 0 | L8: ='Portfolio Allocation'!L8 -> 3724.192 | N8: =(F8+J8)-E8 -> 37.24192 | P8: =VLOOKUP($B8,'Portfolio Allocation'!$B$2:$T$29,15,0) -> 1.3749206 | Q8: =VLOOKUP($B8,'Portfolio Allocation'!$B$2:$T$29,16,0) -> 0.29941829 | S8: =VLOOKUP($B8,'Portfolio Allocation'!$B$2:$T$29,18,0) -> 0.5395584 | T8: =VLOOKUP($B8,'Portfolio Allocation'!$B$2:$T$29,19,0) -> 0.15761568
B9: Direct Equity - Non MO | D9: ='Portfolio Allocation'!D9 -> Jul-23 - Jun-26 | E9: =VLOOKUP($B9,'Portfolio Allocation'!$B$2:$T$29,4,0) -> 150.41406 | F9: =VLOOKUP($B9,'Portfolio Allocation'!$B$2:$T$29,5,0) -> 222.35865 | G9: =IFERROR(F9/$F$16,0) -> 0.21693551 | H9: =IFERROR(G9/$G$4,0) -> 0.21693551 | J9: =VLOOKUP($B9,'Portfolio Allocation'!$B$2:$T$29,9,0) -> 1.8273252 | L9: ='Portfolio Allocation'!L9 -> 6887.3804 | N9: =(F9+J9)-E9 -> 73.771919 | P9: =VLOOKUP($B9,'Portfolio Allocation'!$B$2:$T$29,15,0) -> 0.43578585 | Q9: =VLOOKUP($B9,'Portfolio Allocation'!$B$2:$T$29,16,0) -> 0.069273635 | S9: =VLOOKUP($B9,'Portfolio Allocation'!$B$2:$T$29,18,0) -> 0.32026554 | T9: =VLOOKUP($B9,'Portfolio Allocation'!$B$2:$T$29,19,0) -> 0.072169986
B10: Multi Cap | D10: ='Portfolio Allocation'!D10 -> March 20 - Aug 25 | E10: =VLOOKUP($B10,'Portfolio Allocation'!$B$2:$T$29,4,0) -> 332.69671 | F10: =VLOOKUP($B10,'Portfolio Allocation'!$B$2:$T$29,5,0) -> 361.70793 | G10: =IFERROR(F10/$F$16,0) -> 0.35288618 | H10: =IFERROR(G10/$G$4,0) -> 0.35288618 | J10: =VLOOKUP($B10,'Portfolio Allocation'!$B$2:$T$29,9,0) -> 0 | L10: ='Portfolio Allocation'!L10 -> 2945.7612 | N10: =(F10+J10)-E10 -> 29.011228 | P10: =VLOOKUP($B10,'Portfolio Allocation'!$B$2:$T$29,15,0) -> 0.087685415 | Q10: =VLOOKUP($B10,'Portfolio Allocation'!$B$2:$T$29,16,0) -> 0.024078156 | S10: =VLOOKUP($B10,'Portfolio Allocation'!$B$2:$T$29,18,0) -> 0.093634906 | T10: =VLOOKUP($B10,'Portfolio Allocation'!$B$2:$T$29,19,0) -> 0.026127818
B11: Equity Hybrid | D11: ='Portfolio Allocation'!D11 -> May-22 - Jan-26 | E11: =VLOOKUP($B11,'Portfolio Allocation'!$B$2:$T$29,4,0) -> 96.675688 | F11: =VLOOKUP($B11,'Portfolio Allocation'!$B$2:$T$29,5,0) -> 105.98628 | G11: =IFERROR(F11/$F$16,0) -> 0.10340136 | H11: =IFERROR(G11/$G$4,0) -> 0.10340136 | J11: =VLOOKUP($B11,'Portfolio Allocation'!$B$2:$T$29,9,0) -> 0 | L11: ='Portfolio Allocation'!L11 -> 188.74821 | N11: =(F11+J11)-E11 -> 9.310592 | P11: =VLOOKUP($B11,'Portfolio Allocation'!$B$2:$T$29,15,0) -> 0.10094745 | Q11: =VLOOKUP($B11,'Portfolio Allocation'!$B$2:$T$29,16,0) -> 0.038213701 | S11: =VLOOKUP($B11,'Portfolio Allocation'!$B$2:$T$29,18,0) -> 0.016414568 | T11: =VLOOKUP($B11,'Portfolio Allocation'!$B$2:$T$29,19,0) -> 0.034314373
B12: Mid & Small Cap | D12: ='Portfolio Allocation'!D12 -> Sep-24 - Dec-25 | E12: =VLOOKUP($B12,'Portfolio Allocation'!$B$2:$T$29,4,0) -> 183.99973 | F12: =VLOOKUP($B12,'Portfolio Allocation'!$B$2:$T$29,5,0) -> 246.75783 | G12: =IFERROR(F12/$F$16,0) -> 0.24073962 | H12: =IFERROR(G12/$G$4,0) -> 0.24073962 | J12: =VLOOKUP($B12,'Portfolio Allocation'!$B$2:$T$29,9,0) -> 0.015907185 | L12: ='Portfolio Allocation'!L12 -> 6277.4015 | N12: =(F12+J12)-E12 -> 62.774015 | P12: =VLOOKUP($B12,'Portfolio Allocation'!$B$2:$T$29,15,0) -> 0.34116363 | Q12: =VLOOKUP($B12,'Portfolio Allocation'!$B$2:$T$29,16,0) -> 0.045401409 | S12: =VLOOKUP($B12,'Portfolio Allocation'!$B$2:$T$29,18,0) -> 0.4334171 | T12: =VLOOKUP($B12,'Portfolio Allocation'!$B$2:$T$29,19,0) -> 0.056590232
B13: Small Cap | D13: ='Portfolio Allocation'!D13 -> Oct-24 - Oct-24 | E13: =VLOOKUP($B13,'Portfolio Allocation'!$B$2:$T$29,4,0) -> 1 | F13: =VLOOKUP($B13,'Portfolio Allocation'!$B$2:$T$29,5,0) -> 1.1248249 | G13: =IFERROR(F13/$F$16,0) -> 0.0010973914 | H13: =IFERROR(G13/$G$4,0) -> 0.0010973914 | J13: =VLOOKUP($B13,'Portfolio Allocation'!$B$2:$T$29,9,0) -> 0 | L13: ='Portfolio Allocation'!L13 -> 12.48249 | N13: =(F13+J13)-E13 -> 0.1248249 | P13: =VLOOKUP($B13,'Portfolio Allocation'!$B$2:$T$29,15,0) -> 0.1248249 | Q13: =VLOOKUP($B13,'Portfolio Allocation'!$B$2:$T$29,16,0) -> 0.018808085 | S13: =VLOOKUP($B13,'Portfolio Allocation'!$B$2:$T$29,18,0) -> 0.072427824 | T13: =VLOOKUP($B13,'Portfolio Allocation'!$B$2:$T$29,19,0) -> 0.011138436
B14: SLBM | E14: =VLOOKUP($B14,'Portfolio Allocation'!$B$2:$T$29,4,0) -> 0 | F14: =VLOOKUP($B14,'Portfolio Allocation'!$B$2:$T$29,5,0) -> 0.24478595 | G14: =IFERROR(F14/$F$16,0) -> 0.00023881583 | H14: =IFERROR(G14/$G$4,0) -> 0.00023881583 | J14: =VLOOKUP($B14,'Portfolio Allocation'!$B$2:$T$29,9,0) -> 0 | L14: ='Portfolio Allocation'!L14 -> 24.478595 | N14: =(F14+J14)-E14 -> 0.24478595
B15: LKP Sec Portfolio | D15: ='Portfolio Allocation'!D15 -> Mar-25 - May-26 | E15: =VLOOKUP($B15,'Portfolio Allocation'!$B$2:$T$29,4,0) -> 1.0963805 | F15: =VLOOKUP($B15,'Portfolio Allocation'!$B$2:$T$29,5,0) -> 0.84977725 | G15: =IFERROR(F15/$F$16,0) -> 0.0008290519 | H15: =IFERROR(G15/$G$4,0) -> 0.0008290519 | J15: =VLOOKUP($B15,'Portfolio Allocation'!$B$2:$T$29,9,0) -> 0.00195 | L15: ='Portfolio Allocation'!L15 -> -8.7961095 | N15: =(F15+J15)-E15 -> -0.24465325 | P15: =VLOOKUP($B15,'Portfolio Allocation'!$B$2:$T$29,15,0) -> -0.072034374 | Q15: =VLOOKUP($B15,'Portfolio Allocation'!$B$2:$T$29,16,0) -> 0.069722837 | S15: =VLOOKUP($B15,'Portfolio Allocation'!$B$2:$T$29,18,0) -> -0.10054799 | T15: =VLOOKUP($B15,'Portfolio Allocation'!$B$2:$T$29,19,0) -> 0.09777804
B16: Total | E16: =E4 -> 810.70047 | F16: =F4 -> 1024.9989 | G16: =G4 -> 1 | J16: =J4 -> 1.8451824 | L16: =L4 -> 20734.548 | N16: =N4 -> 216.14357 | P16: ='Portfolio Allocation'!P4 -> 0.26003127 | Q16: ='Portfolio Allocation'!Q4 -> 0.049233916 | S16: ='Portfolio Allocation'!S4 -> 0.22988721 | T16: ='Portfolio Allocation'!T4 -> 0.051674172
B17: * Direct Equity advised by MOSL adds Onesource from unlisted to listed and annualized returns reflect performance of the same; swiggy has been redeemed in May -June 2025.

Sheet Asset Allocation
B1: from Live consol | C1: 2 | D1: 3 | E1: 4 | F1: 6 | G1: Post adjusted value of liquidity in Debt / cash to be allocated from
B2: Asset Class | C2: Market Value in Lakhs | D2: Allocation (%) | E2: Effective Allocation (%) | F2: Liquidity to be assigned | G2: Adjusted Value | H2: Allocation (%) | I2: Effective Allocation (%)
B3: Equity | C3: 1024.9989 | D3: 0.78843032 | E3: 0.72003376 | G3: =C3-F3 -> 1024.9989 | H3: 0.81768588 | I3: 0.7467514
B4: Debt | C4: 45.889164 | D4: 0.035297998 | E4: 0.075495493 | F4: 41.077278 | G4: =C4-F4 -> 4.8118854 | H4: 0.003838649 | I4: 0.045527715
B5: Alternate* | C5: 223.72546 | D5: 0.17208988 | E5: 0.19066432 | G5: =C5-F5 -> 223.72546 | H5: 0.17847547 | I5: 0.19773913
B6: Cash | C6: 5.4365436 | D6: 0.0041817957 | E6: 0.013806424 | F6: 5.4365436 | G6: =C6-F6 -> 0 | H6: 0 | I6: 0.0099817607
B7: Total | C7: =SUM(C3:C6) -> 1300.05 | D7: =SUM(D3:D6) -> 1 | E7: =SUM(E3:E6) -> 1 | F7: =SUM(F3:F6) -> 46.513822 | G7: =SUM(G3:G6) -> 1253.5362 | H7: =SUM(H3:H6) -> 1 | I7: =SUM(I3:I6) -> 1
B9: Note: Pvt investments for Asset allocation are taken at cost. This reflects the actual allocation closer to current realized value.
B12: Particulars | C12: Total Portfolio AUM | D12: Total Portfolio Allocation | E12: Equity Aum in Cr (Sheet) | F12: Allocation of Equity Portfolio | G12: Debt AUM in Cr (Sheet) | H12: Allocation of Debt Portfolio | I12: Cash AUM in Cr (sheet) | J12: Allocation of Cash portfolio | K12: Alternate AUM in Cr (Sheet) | L12: Allocation of Alternate Portfolio
B13: Growth
A14: SG | B14: Stable | C14: =E14+G14+I14+K14 -> 541.90311 | D14: =C14/$C$18 -> 0.41691101 | E14: =SUMIF(Equity!$A:$A,'Asset Allocation'!A14,Equity!$H:$H) -> 538.13468 | F14: =E14/$E$18 -> 0.52513544 | G14: =SUMIF(Debt!$A:$A,'Asset Allocation'!A14,Debt!$F:$F) -> 3.768427 | H14: =G14/$G$18 -> 0.082120193 | I14: 0 | J14: =I14/$I$18 -> 0 | K14: =SUMIF(Alternate!$A:$A,'Asset Allocation'!A14,Alternate!$E:$E) -> 0 | L14: =K14/$K$18 -> 0
A15: EG | B15: Entrepreneur | C15: =E15+G15+I15+K15 -> 191.70115 | D15: =C15/$C$18 -> 0.14748452 | E15: =SUMIF(Equity!$A:$A,'Asset Allocation'!A15,Equity!$H:$H) -> 22.828516 | F15: =E15/$E$18 -> 0.022277068 | G15: =SUMIF(Debt!$A:$A,'Asset Allocation'!A15,Debt!$F:$F) -> 0 | H15: =G15/$G$18 -> 0 | I15: 0 | J15: =I15/$I$18 -> 0 | K15: =SUMIF(Alternate!$A:$A,'Asset Allocation'!A15,Alternate!$E:$E) -> 168.87263 | L15: =K15/$K$18 -> 0.7548208
A16: Liquid | B16: Liquid | C16: =E16+G16+I16+K16 -> 152.5001 | D16: =C16/$C$18 -> 0.11732535 | E16: =SUMIF(Equity!$A:$A,'Asset Allocation'!A16,Equity!$H:$H) -> 105.98628 | F16: =E16/$E$18 -> 0.10342606 | G16: =SUMIF(Debt!$A:$A,'Asset Allocation'!A16,Debt!$F:$F) -> 41.077278 | H16: =G16/$G$18 -> 0.89514114 | I16: =SUMIF(Cash!$A:$A,'Asset Allocation'!A16,Cash!$F:$F) -> 5.4365436 | J16: =I16/$I$18 -> 1 | K16: =SUMIF(Alternate!$A:$A,'Asset Allocation'!A16,Alternate!$E:$E) -> 0 | L16: =K16/$K$18 -> 0
A17: TT | B17: Thematic/Tactical | C17: =E17+G17+I17+K17 -> 413.70088 | D17: =C17/$C$18 -> 0.31827913 | E17: =SUMIF(Equity!$A:$A,'Asset Allocation'!A17,Equity!$H:$H) -> 357.80459 | F17: =E17/$E$18 -> 0.34916143 | G17: =SUMIF(Debt!$A:$A,'Asset Allocation'!A17,Debt!$F:$F) -> 1.0434584 | H17: =G17/$G$18 -> 0.022738668 | I17: 0 | J17: =I17/$I$18 -> 0 | K17: =SUMIF(Alternate!$A:$A,'Asset Allocation'!A17,Alternate!$E:$E) -> 54.852829 | L17: =K17/$K$18 -> 0.2451792
B18: Total | C18: =SUM(C14:C17) -> 1299.8052 | D18: =SUM(D14:D17) -> 1 | E18: =SUM(E13:E17) -> 1024.7541 | F18: =SUM(F13:F17) -> 1 | G18: =SUM(G13:G17) -> 45.889164 | H18: =SUM(H13:H17) -> 1 | I18: =SUM(I13:I17) -> 5.4365436 | J18: =SUM(J13:J17) -> 1 | K18: =SUM(K13:K17) -> 223.72546 | L18: =SUM(L13:L17) -> 1

Sheet Stable Growth
C2: Product | D2: Investment Date Range | E2: Advisor | F2: Investor | G2: Investment at Cost (in crores) | H2: Market Value (in crores) | I2: Allocation (%) | J2: Benchmark | K2: Scheme Absolute (%) | L2: Index Absolute (%) | M2: Scheme XIRR (%) | N2: Index XIRR (%)
C3: Motilal Oswal Founders Fund II | D3: Aug-24 - Oct-24 | E3: MOPWM | F3: Ajay Jaisinghani / Ankita Jaisinghani | G3: 29.9985 | H3: 32.706287 | I3: =H3/$H$16 -> 0.060354492 | J3: S&P BSE 500 TR | K3: 0.090264064 | L3: 0.0078803335 | M3: 0.049043646 | N3: 0.0043587536
C4: Carnelian Bespoke Portfolio | D4: Jan-25 - Dec-25 | E4: Carnelian | F4: Ajay Jaisinghani | G4: 33 | H4: 40.047568 | I4: =H4/$H$16 -> 0.073901713 | J4: S&P BSE 500 TR | K4: 0.21356266 | L4: 0.019115723 | M4: 0.17886855 | N4: 0.016431174
C5: Buoyant Opportunities Portfolio AIF | D5: May-24 - Jun-26 | E5: MOPWM | F5: Ajay Jaisinghani / Ankita Jaisinghani | G5: 70.855886 | H5: 76.047925 | I5: =H5/$H$16 -> 0.14033491 | J5: S&P BSE 500 TR | K5: 0.073276036 | L5: 0.028688756 | M5: 0.11424926 | N5: 0.045162562
C6: 3P India Equity Fund 1 | D6: Apr-23 - Nov-25 | E6: MOPWM | F6: Ajay Jaisinghani / Ankita Jaisinghani | G6: 47.49516 | H6: 52.115602 | I6: =H6/$H$16 -> 0.096171439 | J6: S&P BSE 500 TR | K6: 0.097282361 | L6: 0.094633109 | M6: 0.072618744 | N6: 0.070717308
C7: Helios Flexi Cap Fund Direct (G) | D7: Aug-24 - Nov-25 | E7: MOPWM | F7: Ajay Jaisinghani / Ankita Jaisinghani / Bharat Jaisinghani / Bharat Jaisinghani Family Trust II / Bharat Jaisinghani Family Trust III | G7: 25.318415 | H7: 27.174766 | I7: =H7/$H$16 -> 0.05014691 | J7: Nifty 500 TRI | K7: 0.073320214 | L7: -0.0038231602 | M7: 0.066808715 | N7: -0.0035201839
C8: ICICI Pru India Opportunities Fund | D8: Mar-25 - Mar-26 | E8: MOPWM Dir | F8: Ajay Jaisinghani / Ankita Jaisinghani / Bharat Jaisinghani | G8: 24.854421 | H8: 25.418104 | I8: =H8/$H$16 -> 0.046905255 | J8: Nifty 500 TRI | K8: 0.035939998 | L8: 0.048954901 | M8: 0.055750164 | N8: 0.076058045
C9: Kotak Large & Midcap Fund - Direct- Growth | D9: Mar-20 | E9: MOPWM Dir | F9: Ajay Jaisinghani | G9: 1.5860418 | H9: 2.5003334 | I9: =H9/$H$16 -> 0.0046139861 | J9: Nifty 500 TRI | K9: 0.57646126 | L9: 0.49445855 | M9: 0.23195326 | N9: 0.20958738
C10: Bandhan Large & Mid Cap Fund - Direct Plan - Growth | D10: Apr-26 | E10: MOPWM | F10: Aarti Ajay Jaisinghani / Ajay Jaisinghani / Ankita Jaisinghani | G10: 24.380016 | H10: 24.782832 | I10: =H10/$H$16 -> 0.045732958 | J10: Nifty 500 TRI | K10: 0.016522376 | L10: 0.019394611
C11: Kotak Multicap Fund-Direct Plan-Growth | D11: Apr-26 | E11: MOPWM | F11: Aarti Ajay Jaisinghani / Ajay Jaisinghani | G11: 9.9995 | H11: 10.236297 | I11: =H11/$H$16 -> 0.018889534 | J11: Nifty 500 TRI | K11: 0.023680902 | L11: 0.012127361
C12: Sanshi Fund 1 | D12: Mar-25 | E12: Mukul Agarwal | F12: Aarti Ajay Jaisinghani / Ajay Jaisinghani / Ankita Jaisinghani / Bharat Jaisinghani | G12: 147.49973 | H12: 204.48014 | I12: =H12/$H$16 -> 0.37733709 | J12: Nifty Mid & Smallcap 400 TR | K12: 0.38630864 | L12: 0.051790642 | M12: 0.59185677 | N12: 0.074412158
C13: Molecule Growth Strategy | D13: Oct-24 | E13: Molecule Venture | F13: Ajay Jaisinghani | G13: 1 | H13: 1.1248249 | I13: =H13/$H$16 -> 0.0020756938 | J13: S&P BSE 500 TR | K13: 0.1248249 | L13: 0.018808085 | M13: 0.072427824 | N13: 0.011138436
C14: National Stock Exchange | D14: Dec-22 - Aug-23 | E14: ICICI Bank / MOPWM | F14: Ajay Jaisinghani / Ankita Jaisinghani | G14: 12.085 | H14: 41.5 | I14: =H14/$H$16 -> 0.076581956 | J14: Nifty 500 TRI | K14: 2.4340091 | L14: 0.51558469 | M14: 0.46641998 | N14: 0.13803429
C15: Neo Infra Income Opportunities Fund Share Class A5 | D15: Oct-23 - Feb-26 | G15: 3.5 | H15: 3.768427 | I15: =H15/$H$16 -> 0.0069540605 | J15: CRISIL Short Term | K15: 0.21981394 | L15: 0.10395107 | M15: 0.14966583 | N15: 0.069996265
C16: Total | G16: =SUM(G3:G15) -> 431.57267 | H16: =SUM(H3:H15) -> 541.90311 | I16: =SUM(I3:I15) -> 1

Sheet Entrepreneruial Growth
C2: Product | D2: Investment Date Range | E2: Advisor | F2: Investor | G2: Investment at Cost (in crores) | H2: Market Value (in crores) | I2: Allocation (%) | J2: Benchmark | K2: Scheme Absolute (%) | L2: Index Absolute (%) | M2: Scheme XIRR (%) | N2: Index XIRR (%)
C3: Zepto | D3: Feb-25 | E3: MOPWM | F3: Ajay Jaisinghani | G3: 15.001596 | H3: 22.828516 | I3: =H3/$H$11 -> 0.11510555 | J3: Nifty 500 TRI | K3: 0.52173913 | L3: 0.12527876
C4: Private Equity | D4: 43984 | G4: 136.1593 | H4: 142.78496 | I4: =H4/$H$11 -> 0.71994788
C5: India SME | D5: Sep-24 - Mar-26 | G5: 13.5 | H5: 15.93 | I5: =H5/$H$11 -> 0.080321972 | J5: Nifty 500 TRI | K5: 0.18300652 | L5: -0.096401407 | M5: 0.22696287 | N5: -0.12429736
C6: Baring PE India Fund 6 | D6: Oct-24 - Sep-25 | G6: 2.025 | H6: 1.8842209 | I6: =H6/$H$11 -> 0.009500586 | J6: Nifty 500 TRI | K6: 0 | L6: 0 | M6: 0 | N6: 0
C7: 360 One Special Opportunities Fund - Series 8 - Class A3 (AIF Category II) | D7: Apr-21 - Apr-21 | G7: 1.984236 | H7: 2.9160826 | I7: =H7/$H$11 -> 0.014703421 | J7: Nifty 500 TRI | K7: 0.65590367 | L7: 0.99829501 | M7: 0.10584796 | N7: 0.14302306
C8: Sky Capital Titan Rising Funds 1 | D8: May-25 - Feb-26 | G8: 4.715 | H8: 4.715 | I8: =H8/$H$11 -> 0.023773892 | J8: Alternate Index | K8: 0 | L8: 0 | M8: 0 | N8: 0
C9: Assetgro Fintech Private Limited | D9: Nov-25 - Nov-25 | G9: 0 | H9: 5.0032848 | I9: =H9/$H$11 -> 0.025227476 | J9: Alternate Index | K9: 0 | L9: 0.048322712
C10: Transition Venture Capital fund I | D10: Aug-25 - Oct-25 | G10: 0 | H10: 2.2647385 | I10: =H10/$H$11 -> 0.011419225 | J10: Alternate Index | K10: 0.29413629 | L10: 0.030877525
C11: Total | G11: =SUM(G3:G10) -> 173.38513 | H11: =SUM(H3:H10) -> 198.32681 | I11: =SUM(I3:I10) -> 1

Sheet Thematic,Tactical
C2: Product | D2: Investment Date Range | E2: Advisor | F2: Investor | G2: Investment at Cost (in crores) | H2: Market Value (in crores) | I2: Allocation (%) | J2: Benchmark | K2: Scheme Absolute (%) | L2: Index Absolute (%) | M2: Scheme XIRR (%) | N2: Index XIRR (%)
C3: Aristos Equity Potrfolio - SB | D3: Dec-25 - Dec-25 | E3: Sanjay Bhattacharya | F3: Ajay Jaisinghani / Ankita Jaisinghani | G3: 25 | H3: 25.922903 | I3: =H3/$H$47 -> 0.062958399 | J3: Nifty 50 TRI | K3: 0.03691612 | L3: -0.073733021
C4: Green Lantern Growth Strategy | D4: Jan-25 | E4: Green Lantern | F4: Ajay Jaisinghani / Ankita Jaisinghani | G4: 15.208723 | H4: 17.617651 | I4: =H4/$H$47 -> 0.042787612 | J4: S&P BSE 500 TR | K4: 0.15839126 | L4: 0.079591185 | M4: 0.10670952 | N4: 0.05422844
C5: Fund of Funds (VEC+ Carnelian+Girik Cap+Insightful) | D5: Nov-24 - Nov-24 | E5: MOPWM | F5: Ajay Jaisinghani | G5: 10 | H5: 11.128744 | I5: =H5/$H$47 -> 0.027028141 | J5: Nifty 500 TRI | K5: 0.11287435 | L5: 0.019793346 | M5: 0.080529395 | N5: 0.01429567
C6: Carnelian Bharat Amritkaal Fund | D6: Aug-25 | E6: MOPWM | F6: Ankita Jaisinghani | G6: 15.000043 | H6: 16.008922 | I6: =H6/$H$47 -> 0.038880526 | J6: Nifty 500 TRI | K6: 0.067258447 | L6: -0.10187298 | M6: 0.14816979 | N6: -0.20571077
C7: Svan Investment | D7: Sep-24 - Oct-25 | E7: Svan | F7: Ajay Jaisinghani / Bharat Jaisinghani | G7: 24 | H7: 26.383247 | I7: =H7/$H$47 -> 0.064076426 | J7: S&P BSE 500 TR | K7: 0.099964747 | L7: 0.027818461 | M7: 0.071813414 | N7: 0.02022101
C8: VEC Small and Mid cap fund | D8: Jul-25 | E8: MOPWM | F8: Ajay Jaisinghani / Ankita Jaisinghani | G8: 12.5 | H8: 15.894442 | I8: =H8/$H$47 -> 0.038602491 | J8: S&P BSE 500 TR | K8: 0.27155537 | L8: 0.0037678631
C9: DSP Silver ETF | D9: Sep-25 - Sep-25 | G9: 4.2561917 | H9: 6.5449619 | I9: =H9/$H$47 -> 0.015895609 | J9: MCX Silver | K9: 0.74830014 | L9: 0.82390612
C10: DSP Gold ETF | D10: Jan-26 - Jan-26 | G10: 53.585434 | H10: 48.307867 | I10: =H10/$H$47 -> 0.11732428 | J10: MCX GOLD SPOT | K10: -0.098488836 | L10: -0.091201257
C11: 15% K M Global - Credit Private Limited | D11: Sep-20 - Mar-24 | G11: 0.70001498 | H11: 1.0434584 | I11: =H11/$H$47 -> 0.0025342252 | J11: CRISIL Short Term | K11: 0.49062302 | L11: 0.24620557 | M11: 0.12367324 | N11: 0.067806676
C12: LKP Sec Portfolio | D12: 0 | E12: LKP | F12: Bharat Jaisinghani | G12: 1.0963805 | H12: 0.84977725 | I12: =H12/$H$47 -> 0.0020638358 | J12: 0 | K12: -0.072034374 | L12: 0.069722837 | M12: -0.10054799 | N12: 0.09777804
C13: Bharat Parenterals Ltd | D13: Nov-24 | E13: MOPWM | F13: Ankita Jaisinghani | G13: 0.090745032 | H13: 0.08442 | I13: =H13/$H$47 -> 0.00020502904 | J13: Nifty Mid & Smallcap 400 TR | K13: -0.066140798 | L13: 0.077828824 | M13: -0.041599378 | N13: 0.047544053
C14: Birla Cable Ltd. | D14: Aug-23 - Jan-24 | E14: MOPWM | F14: Ajay Jaisinghani / Bharat Jaisinghani | G14: 0.36973099 | H14: 0.3127479 | I14: =H14/$H$47 -> 0.00075956413 | J14: Nifty Mid & Smallcap 400 TR | K14: -0.29805272 | L14: 0.47520331 | M14: -0.16933851 | N14: 0.2278928
C15: BSE Ltd. | D15: Jul-23 - Oct-24 | E15: MOPWM | F15: Ajay Jaisinghani | G15: 0 | H15: 15.4624 | I15: =H15/$H$47 -> 0.037553199 | J15: Nifty Mid & Smallcap 400 TR | K15: 3.3766661 | L15: 0.15307721 | M15: 1.3370817 | N15: 0.092957088
C16: Deepak Fert | D16: Jul-24 - Aug-24 | E16: HDFC Bank / MOPWM | F16: Ajay Jaisinghani | G16: 2.5226066 | H16: 4.0400237 | I16: =H16/$H$47 -> 0.0098119188 | J16: Nifty Mid & Smallcap 400 TR | K16: 0.62054365 | L16: 0.056710201 | M16: 0.29264398 | N16: 0.029473165
C17: Fractal Analytics Limited | D17: Jul-25 - Jul-25 | E17: ICICI Bank | F17: Ajay Jaisinghani | G17: 17.687888 | H17: 16.032861 | I17: =H17/$H$47 -> 0.038938666 | J17: Nifty Mid & Smallcap 400 TR | K17: -0.093568367 | L17: 0.030529841
C18: IFB Inds. | D18: Sep-25 - Sep-25 | E18: MOPWM | F18: Ajay Jaisinghani | G18: 2.386564 | H18: 2.0363229 | I18: =H18/$H$47 -> 0.0049455738 | J18: Nifty Mid & Smallcap 400 TR | K18: -0.26925924 | L18: -0.013144243
C19: Infinium Pharmachem Ltd. | D19: Nov-24 | E19: MOPWM | F19: Ankita Jaisinghani | G19: 0.297729 | H19: 0.15424 | I19: =H19/$H$47 -> 0.00037459938 | J19: Nifty Mid & Smallcap 400 TR | K19: -0.40075965 | L19: 0.074973291 | M19: -0.2797844 | N19: 0.04712806
C20: Insolation Energy Ltd | D20: Dec-24 | E20: ICICI Bank | F20: Ajay Jaisinghani / Bharat Jaisinghani | G20: 9.9681562 | H20: 3.5238812 | I20: =H20/$H$47 -> 0.0085583747 | J20: Nifty Mid & Smallcap 400 TR | K20: -0.64648616 | L20: 0.018308548 | M20: -0.48857966 | N20: 0.011768684
C21: Jaro Education | D21: May-24 | E21: ICICI Bank | F21: Ajay Jaisinghani | G21: 7.500035 | H21: 5.7957246 | I21: =H21/$H$47 -> 0.014075952 | J21: Nifty Mid & Smallcap 400 TR | K21: -0.22724033 | L21: 0.13100728 | M21: -0.14457367 | N21: 0.07557573
C22: Kingfa Science & Technology Ltd. | D22: Jul-24 - Jun-25 | E22: HDFC Bank / MOPWM | F22: Ajay Jaisinghani | G22: 5.4945529 | H22: 10.05693 | I22: =H22/$H$47 -> 0.02442505 | J22: Nifty Mid & Smallcap 400 TR | K22: 0.8319563 | L22: 0.063249664 | M22: 0.50014291 | N22: 0.042839798
C23: Man Industries | D23: May-24 - Jul-25 | E23: HDFC Bank / MOPWM | F23: Ajay Jaisinghani | G23: 19.271126 | H23: 33.899698 | I23: =H23/$H$47 -> 0.082331469 | J23: Nifty Mid & Smallcap 400 TR | K23: 0.75909275 | L23: 0.065319298 | M23: 0.63026349 | N23: 0.058052889
C24: Manorama Industries Ltd. | D24: Aug-23 - Jan-26 | E24: HDFC Bank / MOPWM | F24: Ajay Jaisinghani | G24: 15.182156 | H24: 25.053337 | I24: =H24/$H$47 -> 0.060846503 | J24: Nifty Mid & Smallcap 400 TR | K24: 0.65085739 | L24: -0.11210566 | M24: 0.50582085 | N24: 0.050758591
C25: Neuland Labs. | D25: Jan-24 - May-25 | E25: MOPWM | F25: Ajay Jaisinghani | G25: 4.5809307 | H25: 8.6164675 | I25: =H25/$H$47 -> 0.02092663 | J25: Nifty Mid & Smallcap 400 TR | K25: 0.88248264 | L25: 0.11527542 | M25: 0.60834972 | N25: 0.08869355
C26: Nuvama Wealth Management Ltd | D26: Jun-24 - Jun-24 | E26: MOPWM | F26: Ajay Jaisinghani | G26: 0.9468099 | H26: 1.7165075 | I26: =H26/$H$47 -> 0.004168845 | J26: Nifty Mid & Smallcap 400 TR | K26: 0.85578171 | L26: 0.089868933 | M26: 0.36995774 | N26: 0.043723109
C27: Parth Electrical & Engineering | D27: Apr-25 - Apr-25 | E27: ICICI Bank | F27: Ajay Jaisinghani | G27: 1.003 | H27: 3.683075 | I27: =H27/$H$47 -> 0.0089450053 | J27: Nifty Mid & Smallcap 400 TR | K27: 2.6720588 | L27: 0.17715311
C28: PG Electro. | D28: Mar-26 | E28: MOPWM | F28: Aarti Ajay Jaisinghani | G28: 9.4396845 | H28: 10.03806 | I28: =H28/$H$47 -> 0.024379221 | J28: Nifty Mid & Smallcap 400 TR | K28: 0.063389351 | L28: 0.14383958
C29: Smart Works | D29: Sep-24 | E29: HDFC Bank | F29: Ajay Jaisinghani / Bharat Jaisinghani | G29: 13.000005 | H29: 14.025561 | I29: =H29/$H$47 -> 0.034063579 | J29: Nifty Mid & Smallcap 400 TR | K29: 0.078888889 | L29: 0.0088763045 | M29: 0.043697998 | N29: 0.0049901217
C30: Sterlite Grid 5 | E30: HDFC Bank | F30: Ajay Jaisinghani | G30: 0.036594 | H30: 0.036594 | I30: =H30/$H$47 -> 8.8875063e-05 | J30: Nifty Mid & Smallcap 400 TR
C31: Sterlite Power Transmission | E31: HDFC Bank | F31: Ajay Jaisinghani | G31: 0.05586 | H31: 0.05586 | I31: =H31/$H$47 -> 0.00013566598 | J31: Nifty Mid & Smallcap 400 TR
C32: Sterlite Tech | E32: HDFC Bank | F32: Ajay Jaisinghani | G32: 0.11361775 | H32: 0.11361775 | I32: =H32/$H$47 -> 0.00027594099 | J32: Nifty Mid & Smallcap 400 TR
C33: STLNETWORK | E33: HDFC Bank | F33: Ajay Jaisinghani | G33: 0.0042476 | H33: 0.0042476 | I33: =H33/$H$47 -> 1.0316055e-05 | J33: Nifty Mid & Smallcap 400 TR
C34: Tatva Chintan Pharma Chem Limi | D34: Aug-25 | E34: MOPWM | F34: Ajay Jaisinghani | G34: 2.230075 | H34: 2.5301246 | I34: =H34/$H$47 -> 0.0061448592 | J34: Nifty Mid & Smallcap 400 TR | K34: 0.13509478 | L34: 0.066167369 | M34: 0.16837136 | N34: 0.081823936
C35: Tech Mahindra Ltd. | D35: Jul-23 - Oct-23 | E35: MOPWM | F35: Ajay Jaisinghani | G35: 2.4795522 | H35: 3.05631 | I35: =H35/$H$47 -> 0.0074227946 | J35: Nifty Mid & Smallcap 400 TR | K35: 0.33677765 | L35: 0.64391933 | M35: 0.11336035 | N35: 0.19020486
C36: Vedanta | D36: Jul-24 | E36: HDFC Bank / MOPWM | F36: Ajay Jaisinghani | G36: 6.8212228 | H36: 8.19936 | I36: =H36/$H$47 -> 0.01991361 | J36: Nifty Mid & Smallcap 400 TR | K36: 0.39313878 | L36: 0.065394196 | M36: 0.27076382 | N36: 0.042134789
C37: Yash High Voltage Ltd. | D37: Apr-24 - Apr-24 | E37: ICICI Bank | F37: Ajay Jaisinghani | G37: 0.84112173 | H37: 10.207312 | I37: =H37/$H$47 -> 0.02479028 | J37: Nifty Mid & Smallcap 400 TR | K37: 12.20719 | L37: 0.23510572 | M37: 1.4417536 | N37: 0.10043599
C38: Zaggle Prepaid Ocean Services Ltd. | D38: Sep-23 - Nov-24 | E38: MOPWM | F38: Ajay Jaisinghani / Ankita Jaisinghani | G38: 1.323394 | H38: 1.28371 | I38: =H38/$H$47 -> 0.0031177189 | J38: Nifty Mid & Smallcap 400 TR | K38: -0.029986535 | L38: 0.34356441 | M38: -0.012906021 | N38: 0.13305877
C39: Clean Max Enviro Energy Solutions Ltd | D39: Jan-26 | E39: ICICI Bank / MOPWM | F39: Ajay Jaisinghani / Ankita Jaisinghani | G39: 18.771598 | H39: 25.917444 | I39: =H39/$H$47 -> 0.06294514 | J39: Nifty Mid & Smallcap 400 TR | K39: 0.38067328 | L39: 0.083451406 | M39: 1.180873 | N39: 0.2137857
C40: M/S Grand Continent Hotels | D40: Feb-24 | E40: Private Investments | F40: Ajay Jaisinghani | G40: 1.627725 | H40: 1.627725 | I40: =H40/$H$47 -> 0.0039532208 | J40: Nifty Mid & Smallcap 400 TR | K40: 2.220446e-16 | L40: 0.2784901
C41: Vedanta Oil & Gas Ltd | D41: Aug-25 | E41: HDFC Bank / MOPWM | F41: Ajay Jaisinghani | G41: 1.0672525 | H41: 0.7429 | I41: =H41/$H$47 -> 0.0018042653 | J41: Nifty Mid & Smallcap 400 TR | K41: -0.7342847 | L41: 0.074920279
...

Sheet Liquid
C2: Product | D2: Investment Date Range | E2: Advisor | F2: Investor | G2: Investment at Cost (in crores) | H2: Market Value (in crores) | I2: Allocation (%) | J2: Benchmark | K2: Scheme Absolute (%) | L2: Index Absolute (%) | M2: Scheme XIRR (%) | N2: Index XIRR (%)
C3: Aditya Birla SL Balanced Advantage Fund(G) | D3: Jun-23 - Nov-25 | E3: MOPWM / MOPWM Dir | F3: Aarti Ajay Jaisinghani / Ankita Jaisinghani / Bharat Jaisinghani / Ajay Jaisinghani | G3: 26.867902 | H3: 29.582027 | I3: =H3/$H$20 -> 0.19559271 | J3: Balanced Index | K3: 0.10101738 | L3: 0.065388883 | M3: 0.083728281 | N3: 0.055001131
C4: HDFC Balanced Advantage Fund | D4: May-22 - Jul-24 | E4: MOPWM Dir / MOPWM Reg | F4: Bharat Jaisinghani / Ajay Jaisinghani / Ankita Jaisinghani | G4: 7.2297465 | H4: 10.869689 | I4: =H4/$H$20 -> 0.071869039 | J4: Balanced Index | K4: 0.49988855 | L4: 0.35274615 | M4: 0.1349234 | N4: 0.099197882
C5: ICICI Pru Balanced Advantage Fund | D5: Sep-22 | E5: MOPWM Dir / MOPWM Reg | F5: Ajay Jaisinghani / Bharat Jaisinghani / Ankita Jaisinghani | G5: 21.597723 | H5: 22.317241 | I5: =H5/$H$20 -> 0.14755884 | J5: Balanced Index | K5: 0.037451584 | L5: 0.016809687 | M5: 0.04462271 | N5: 0.020225558
C6: ICICI Prudential Equity Savings Fund - Direct Plan | D6: Nov-25 | E6: MOPWM | F6: Ajay Jaisinghani | G6: 23.281984 | H6: 23.179461 | I6: =H6/$H$20 -> 0.15325974 | J6: Equity Savings Index | K6: -0.0040276689 | L6: -0.061122933 | M6: -0.47355465 | N6: -0.10196347
C7: WhiteOak Capital Multi Asset Allocation Fund-Direct(G) | D7: Jul-24 | E7: MOPWM | F7: Ajay Jaisinghani / Ankita Jaisinghani / Bharat Jaisinghani | G7: 17.698332 | H7: 20.037862 | I7: =H7/$H$20 -> 0.13248787 | J7: Balanced Index | K7: 0.13218928 | L7: 0.011121138 | M7: 0.12581871 | N7: 0.010808691
C8: Aditya Birla SL Liquid Fund-(DD)-Direct | D8: Jul-19 - Sep-25 | G8: 0 | H8: 0.07624559 | I8: =H8/$H$20 -> 0.00050412642 | J8: CRISIL Liquid Fund Index | M8: 0.0075873286 | N8: 0.057610968
C9: Aditya Birla SL Liquid Fund-Direct (G) | D9: Jul-19 - Jul-19 | G9: 0.053714628 | H9: 0.079441248 | I9: =H9/$H$20 -> 0.00052525572 | J9: CRISIL Liquid Fund Index | M9: 0.057565376 | N9: 0.057437971
C10: HDFC Liquid Fund -Direct(G) | D10: Mar-20 - Mar-20 | G10: 0.014284307 | H10: 0.019483298 | I10: =H10/$H$20 -> 0.00012882116 | J10: CRISIL Liquid Fund Index | M10: 0.030159518 | N10: 0.046286681
C11: HDFC Overnight Fund - Direct - G | D11: Jul-19 - Jul-19 | G11: 0.054356288 | H11: 0.06067928 | I11: =H11/$H$20 -> 0.00040120391 | J11: CRISIL Liquid Fund Index | M11: 0.015894654 | N11: 0.057519111
C12: HSBC Liquid Fund-Direct(DD) | D12: Jul-25 - Apr-26 | G12: 2.744886 | H12: 2.8740049 | I12: =H12/$H$20 -> 0.019002565 | J12: CRISIL Liquid Fund Index | M12: 0.063692632 | N12: 0.059854713
C13: ICICI Pru Liquid Fund-Direct(G) | D13: Jul-19 - Jul-19 | G13: 0.055192263 | H13: 0.077342732 | I13: =H13/$H$20 -> 0.0005113806 | J13: CRISIL Liquid Fund Index | M13: 0.049542978 | N13: 0.057519111
C14: Kotak Liquid-Direct (DD) | D14: Jul-19 - Jul-19 | G14: 0.063572507 | H14: 0.093638682 | I14: =H14/$H$20 -> 0.0006191274 | J14: CRISIL Liquid Fund Index | M14: 0.057088867 | N14: 0.057512018
C15: Mirae Asset Cash Management Fund-Direct(G) | D15: Apr-26 - Apr-26 | G15: 0.8972947 | H15: 0.8986005 | I15: =H15/$H$20 -> 0.0059414355 | J15: CRISIL Liquid Fund Index | M15: 0 | N15: 0
C16: Nippon India ETF Nifty 1D Rate Liquid Bees-IDCW | D16: Jul-25 - Jul-25 | G16: 3.7698115 | H16: 4.0189932 | I16: =H16/$H$20 -> 0.026573087 | J16: Nifty 50 Arbitrage | K16: 0.033220446 | L16: 0.033721467 | M16: 0.072971854 | N16: 0.074066815
C17: Kotak Equity Arbitrage Scheme(G) | D17: May-25 - May-25 | G17: 2.3963149 | H17: 2.5510449 | I17: =H17/$H$20 -> 0.016867194 | J17: Nifty 50 Arbitrage | K17: 0.033220446 | L17: 0.033721467 | M17: 0.072971854 | N17: 0.074066815
C18: Invesco India Arbitrage Fund(G) | D18: Nov-25 - Nov-25 | G18: 2.6026159 | H18: 2.7030789 | I18: =H18/$H$20 -> 0.017872424 | J18: Nifty 50 Arbitrage | K18: 0.033220446 | L18: 0.033721467 | M18: 0.072971854 | N18: 0.074066815
C19: Motilal Oswal Arbitrage Fund Direct (G) | D19: May-25 - May-26 | G19: 30.985244 | H19: 31.804161 | I19: =H19/$H$20 -> 0.21028519 | J19: Nifty 50 Arbitrage | K19: 0.033220446 | L19: 0.033721467 | M19: 0.072971854 | N19: 0.074066815
C20: Total | G20: =SUM(G3:G19) -> 140.31297 | H20: =SUM(H3:H19) -> 151.24299 | I20: =SUM(I3:I19) -> 1

Sheet Equity
E1: Highlighted Dates represent investments < 1 year
A2: Allocation | B2: Product | C2: Advisor | D2: Investor | E2: Investment Date Range | F2: Quantity | G2: Investment at Cost (in crores) | H2: Market Value (in crores) | I2: Allocation (%) | J2: Benchmark | K2: Scheme Absolute (%) | L2: Index Absolute (%) | M2: Scheme XIRR (%) | N2: Index XIRR (%) | R2: =19456-19522 -> -66
B3: Multi Cap | E3: 395322 | G3: =SUM(G4:G16) -> 332.69671 | H3: =SUM(H4:H16) -> 361.70793 | I3: =SUM(I4:I16) -> 0.35288618 | K3: 0.087685415 | L3: 0.024078156 | M3: 0.093634906 | N3: 0.026127818
A4: SG | B4: Motilal Oswal Founders Fund II | C4: MOPWM | D4: Ajay Jaisinghani / Ankita Jaisinghani | E4: Aug-24 - Oct-24 | F4: 28410850 | G4: 29.9985 | H4: 32.706287 | I4: =H4/$H$73 -> 0.031908608 | J4: S&P BSE 500 TR | K4: 0.090264064 | L4: 0.0078803335 | M4: 0.049043646 | N4: 0.0043587536
A5: SG | B5: Carnelian Bespoke Portfolio | C5: Carnelian | D5: Ajay Jaisinghani | E5: Jan-25 - Dec-25 | F5: 0 | G5: 33 | H5: 40.047568 | I5: =H5/$H$73 -> 0.039070841 | J5: S&P BSE 500 TR | K5: 0.21356266 | L5: 0.019115723 | M5: 0.17886855 | N5: 0.016431174
A6: SG | B6: Buoyant Opportunities Portfolio AIF | C6: MOPWM | D6: Ajay Jaisinghani / Ankita Jaisinghani | E6: May-24 - Jun-26 | F6: 5335610.6 | G6: 70.855886 | H6: 76.047925 | I6: =H6/$H$73 -> 0.07419318 | J6: S&P BSE 500 TR | K6: 0.073276036 | L6: 0.028688756 | M6: 0.11424926 | N6: 0.045162562
A7: SG | B7: 3P India Equity Fund 1 | C7: MOPWM | D7: Ajay Jaisinghani / Ankita Jaisinghani | E7: Apr-23 - Nov-25 | F7: 3470532.7 | G7: 47.49516 | H7: 52.115602 | I7: =H7/$H$73 -> 0.050844546 | J7: S&P BSE 500 TR | K7: 0.097282361 | L7: 0.094633109 | M7: 0.072618744 | N7: 0.070717308
A8: TT | B8: Aristos Equity Potrfolio - SB | C8: Sanjay Bhattacharya | D8: Ajay Jaisinghani / Ankita Jaisinghani | E8: Dec-25 - Dec-25 | F8: 0 | G8: 25 | H8: 25.922903 | I8: =H8/$H$73 -> 0.025290665 | J8: Nifty 50 TRI | K8: 0.03691612 | L8: -0.073733021
A9: TT | B9: Green Lantern Growth Strategy | C9: Green Lantern | D9: Ajay Jaisinghani / Ankita Jaisinghani | E9: Jan-25 | F9: 0 | G9: 15.208723 | H9: 17.617651 | I9: =H9/$H$73 -> 0.017187972 | J9: S&P BSE 500 TR | K9: 0.15839126 | L9: 0.079591185 | M9: 0.10670952 | N9: 0.05422844
A10: TT | B10: Fund of Funds (VEC+ Carnelian+Girik Cap+Insightful) | C10: MOPWM | D10: Ajay Jaisinghani | E10: Nov-24 - Nov-24 | F10: 99995 | G10: 10 | H10: 11.128744 | I10: =H10/$H$73 -> 0.010857323 | J10: Nifty 500 TRI | K10: 0.11287435 | L10: 0.019793346 | M10: 0.080529395 | N10: 0.01429567
A11: TT | B11: Carnelian Bharat Amritkaal Fund | C11: MOPWM | D11: Ankita Jaisinghani | E11: Aug-25 | F11: 12993095 | G11: 15.000043 | H11: 16.008922 | I11: =H11/$H$73 -> 0.015618478 | J11: Nifty 500 TRI | K11: 0.067258447 | L11: -0.10187298 | M11: 0.14816979 | N11: -0.20571077
A12: SG | B12: Helios Flexi Cap Fund Direct (G) | C12: MOPWM | D12: Ajay Jaisinghani / Ankita Jaisinghani / Bharat Jaisinghani / Bharat Jaisinghani Family Trust II / Bharat Jaisinghani Family Trust III | E12: Aug-24 - Nov-25 | F12: 17123356 | G12: 25.318415 | H12: 27.174766 | I12: =H12/$H$73 -> 0.026511997 | J12: Nifty 500 TRI | K12: 0.073320214 | L12: -0.0038231602 | M12: 0.066808715 | N12: -0.0035201839
A13: SG | B13: ICICI Pru India Opportunities Fund | C13: MOPWM Dir | D13: Ajay Jaisinghani / Ankita Jaisinghani / Bharat Jaisinghani | E13: Mar-25 - Mar-26 | F13: 6446386.9 | G13: 24.854421 | H13: 25.418104 | I13: =H13/$H$73 -> 0.024798178 | J13: Nifty 500 TRI | K13: 0.035939998 | L13: 0.048954901 | M13: 0.055750164 | N13: 0.076058045
A14: SG | B14: Kotak Large & Midcap Fund - Direct- Growth | C14: MOPWM Dir | D14: Ajay Jaisinghani | E14: Mar-20 | F14: 61946.481 | G14: 1.5860418 | H14: 2.5003334 | I14: =H14/$H$73 -> 0.0024393524 | J14: Nifty 500 TRI | K14: 0.57646126 | L14: 0.49445855 | M14: 0.23195326 | N14: 0.20958738
A15: SG | B15: Bandhan Large & Mid Cap Fund - Direct Plan - Growth | C15: MOPWM | D15: Aarti Ajay Jaisinghani / Ajay Jaisinghani / Ankita Jaisinghani | E15: Apr-26 | F15: 1517142.9 | G15: 24.380016 | H15: 24.782832 | I15: =H15/$H$73 -> 0.0241784 | J15: Nifty 500 TRI | K15: 0.016522376 | L15: 0.019394611
A16: SG | B16: Kotak Multicap Fund-Direct Plan-Growth | C16: MOPWM | D16: Aarti Ajay Jaisinghani / Ajay Jaisinghani | E16: Apr-26 | F16: 4795641.7 | G16: 9.9995 | H16: 10.236297 | I16: =H16/$H$73 -> 0.0099866426 | J16: Nifty 500 TRI | K16: 0.023680902 | L16: 0.012127361
B17: Mid & Small Cap | E17: 42997 | G17: =SUM(G18:G20) -> 183.99973 | H17: =SUM(H18:H20) -> 246.75783 | I17: =SUM(I18:I20) -> 0.24073962 | K17: 0.34116363 | L17: 0.045401409 | M17: 0.4334171 | N17: 0.056590232
A18: TT | B18: Svan Investment | C18: Svan | D18: Ajay Jaisinghani / Bharat Jaisinghani | E18: Sep-24 - Oct-25 | F18: 0 | G18: 24 | H18: 26.383247 | I18: =H18/$H$73 -> 0.025739782 | J18: S&P BSE 500 TR | K18: 0.099964747 | L18: 0.027818461 | M18: 0.071813414 | N18: 0.02022101
A19: SG | B19: Sanshi Fund 1 | C19: Mukul Agarwal | D19: Aarti Ajay Jaisinghani / Ajay Jaisinghani / Ankita Jaisinghani / Bharat Jaisinghani | E19: Mar-25 | F19: 0 | G19: 147.49973 | H19: 204.48014 | I19: =H19/$H$73 -> 0.19949305 | J19: Nifty Mid & Smallcap 400 TR | K19: 0.38630864 | L19: 0.051790642 | M19: 0.59185677 | N19: 0.074412158
A20: TT | B20: VEC Small and Mid cap fund | C20: MOPWM | D20: Ajay Jaisinghani / Ankita Jaisinghani | E20: Jul-25 | F20: 0 | G20: 12.5 | H20: 15.894442 | I20: =H20/$H$73 -> 0.01550679 | J20: S&P BSE 500 TR | K20: 0.27155537 | L20: 0.0037678631
B21: Equity Hybrid | E21: 42997 | G21: =SUM(G22:G26) -> 96.675688 | H21: =SUM(H22:H26) -> 105.98628 | I21: =SUM(I22:I26) -> 0.10340136 | K21: 0.10094745 | L21: 0.038213701 | M21: 0.016414568 | N21: 0.034314373
A22: Liquid | B22: Aditya Birla SL Balanced Advantage Fund(G) | C22: MOPWM / MOPWM Dir | D22: Aarti Ajay Jaisinghani / Ankita Jaisinghani / Bharat Jaisinghani / Ajay Jaisinghani | E22: Jun-23 - Nov-25 | F22: 2437030.6 | G22: 26.867902 | H22: 29.582027 | I22: =H22/$H$73 -> 0.028860546 | J22: Balanced Index | K22: 0.10101738 | L22: 0.065388883 | M22: 0.083728281 | N22: 0.055001131
A23: Liquid | B23: HDFC Balanced Advantage Fund | C23: MOPWM Dir / MOPWM Reg | D23: Bharat Jaisinghani / Ajay Jaisinghani / Ankita Jaisinghani | E23: May-22 - Jul-24 | F23: 206861.5 | G23: 7.2297465 | H23: 10.869689 | I23: =H23/$H$73 -> 0.010604586 | J23: Balanced Index | K23: 0.49988855 | L23: 0.35274615 | M23: 0.1349234 | N23: 0.099197882
A24: Liquid | B24: ICICI Pru Balanced Advantage Fund | C24: MOPWM Dir / MOPWM Reg | D24: Ajay Jaisinghani / Bharat Jaisinghani / Ankita Jaisinghani | E24: Sep-22 | F24: 2610585.5 | G24: 21.597723 | H24: 22.317241 | I24: =H24/$H$73 -> 0.021772942 | J24: Balanced Index | K24: 0.037451584 | L24: 0.016809687 | M24: 0.04462271 | N24: 0.020225558
A25: Liquid | B25: ICICI Prudential Equity Savings Fund - Direct Plan | C25: MOPWM | D25: Ajay Jaisinghani | E25: Nov-25 | F25: 9320249.9 | G25: 23.281984 | H25: 23.179461 | I25: =H25/$H$73 -> 0.022614134 | J25: Equity Savings Index | K25: -0.0040276689 | L25: -0.061122933
A26: Liquid | B26: WhiteOak Capital Multi Asset Allocation Fund-Direct(G) | C26: MOPWM | D26: Ajay Jaisinghani / Ankita Jaisinghani / Bharat Jaisinghani | E26: Jul-24 | F26: 12334787 | G26: 17.698332 | H26: 20.037862 | I26: =H26/$H$73 -> 0.019549155 | J26: Balanced Index | K26: 0.13218928 | L26: 0.011121138 | M26: 0.12581871 | N26: 0.010808691
B27: Small Cap | E27: 173635 | G27: =G28 -> 1 | H27: =H28 -> 1.1248249 | I27: =SUM(I28) -> 0.0010973914 | K27: 0.1248249 | L27: 0.018808085 | M27: 0.072427824 | N27: 0.011138436
A28: SG | B28: Molecule Growth Strategy | C28: Molecule Venture | D28: Ajay Jaisinghani | E28: Oct-24 | F28: 0 | G28: 1 | H28: 1.1248249 | I28: =H28/$H$73 -> 0.0010973914 | J28: S&P BSE 500 TR | K28: 0.1248249 | L28: 0.018808085 | M28: 0.072427824 | N28: 0.011138436
A29: TT | B29: Direct Equity - Non MO | C29: Demat | E29: 882055 | G29: =SUM(G30:G63) -> 150.41406 | H29: =SUM(H30:H63) -> 222.35865 | I29: =SUM(I30:I63) -> 0.21693551 | K29: 0.43578585 | L29: 0.069273635 | M29: 0.32026554 | N29: 0.072169986
B30: Bharat Parenterals Ltd | C30: MOPWM | D30: Ankita Jaisinghani | E30: Nov-24 | F30: 603 | G30: 0.090745032 | H30: 0.08442 | I30: =H30/$H$73 -> 8.2361068e-05 | J30: Nifty Mid & Smallcap 400 TR | K30: -0.066140798 | L30: 0.077828824 | M30: -0.041599378 | N30: 0.047544053
B31: Birla Cable Ltd. | C31: MOPWM | D31: Ajay Jaisinghani / Bharat Jaisinghani | E31: Aug-23 - Jan-24 | F31: 15193 | G31: 0.36973099 | H31: 0.3127479 | I31: =H31/$H$73 -> 0.00030512025 | J31: Nifty Mid & Smallcap 400 TR | K31: -0.29805272 | L31: 0.47520331 | M31: -0.16933851 | N31: 0.2278928
B32: BSE Ltd. | C32: MOPWM | D32: Ajay Jaisinghani | E32: Jul-23 - Oct-24 | F32: 40000 | G32: 0 | H32: 15.4624 | I32: =H32/$H$73 -> 0.015085285 | J32: Nifty Mid & Smallcap 400 TR | K32: 3.3766661 | L32: 0.15307721 | M32: 1.3370817 | N32: 0.092957088
B33: Clean Max Enviro Energy Solutions Ltd | C33: ICICI Bank / MOPWM | D33: Ajay Jaisinghani / Ankita Jaisinghani | E33: Jan-26 | F33: 189934 | G33: 18.771598 | H33: 25.917444 | I33: =H33/$H$73 -> 0.025285339 | J33: Nifty Mid & Smallcap 400 TR | K33: 0.38067328 | L33: 0.083451406
B34: Deepak Fert | C34: HDFC Bank / MOPWM | D34: Ajay Jaisinghani | E34: Jul-24 - Aug-24 | F34: 25930 | G34: 2.5226066 | H34: 4.0400237 | I34: =H34/$H$73 -> 0.0039414909 | J34: Nifty Mid & Smallcap 400 TR | K34: 0.62054365 | L34: 0.056710201 | M34: 0.29264398 | N34: 0.029473165
B35: Fractal Analytics Limited | C35: ICICI Bank | D35: Ajay Jaisinghani | E35: Jul-25 - Jul-25 | F35: 180185 | G35: 17.687888 | H35: 16.032861 | I35: =H35/$H$73 -> 0.015641833 | J35: Nifty Mid & Smallcap 400 TR | K35: -0.093568367 | L35: 0.030529841
B36: M/S Grand Continent Hotels | C36: Private Investments | D36: Ajay Jaisinghani | E36: Feb-24 | F36: 262125 | G36: 1.627725 | H36: 1.627725 | I36: =H36/$H$73 -> 0.0015880262 | J36: Nifty Mid & Smallcap 400 TR | K36: 2.220446e-16 | L36: 0.2784901 | M36: -0.20421218 | N36: 0.11246662
B37: IFB Inds. | C37: MOPWM | D37: Ajay Jaisinghani | E37: Sep-25 - Sep-25 | F37: 15772 | G37: 2.386564 | H37: 2.0363229 | I37: =H37/$H$73 -> 0.0019866587 | J37: Nifty Mid & Smallcap 400 TR | K37: -0.26925924 | L37: -0.013144243
B38: Infinium Pharmachem Ltd. | C38: MOPWM | D38: Ankita Jaisinghani | E38: Nov-24 | F38: 8000 | G38: 0.297729 | H38: 0.15424 | I38: =H38/$H$73 -> 0.00015047822 | J38: Nifty Mid & Smallcap 400 TR | K38: -0.40075965 | L38: 0.074973291 | M38: -0.2797844 | N38: 0.04712806
B39: Insolation Energy Ltd | C39: ICICI Bank | D39: Ajay Jaisinghani / Bharat Jaisinghani | E39: Dec-24 | F39: 303260 | G39: 9.9681562 | H39: 3.5238812 | I39: =H39/$H$73 -> 0.0034379367 | J39: Nifty Mid & Smallcap 400 TR | K39: -0.64648616 | L39: 0.018308548 | M39: -0.48857966 | N39: 0.011768684
B40: Jaro Education | C40: ICICI Bank | D40: Ajay Jaisinghani | E40: May-24 | F40: 116979 | G40: 7.500035 | H40: 5.7957246 | I40: =H40/$H$73 -> 0.0056543717 | J40: Nifty Mid & Smallcap 400 TR | K40: -0.22724033 | L40: 0.13100728 | M40: -0.14457367 | N40: 0.07557573
...

Sheet Month on Month Equity Change
C1: Valuations as on 30th June 2026 | D1: =10^2 -> 100 | O1: Linked | P1: Linked
C2: Category | D2: Market Value as on 31st May 2026 (in Cr) | E2: Investments (in Cr) | F2: Redemptions (in Cr) | G2: Dividend / Interest | H2: Market Value as on 30th June 2026 (in Crs) | I2: Aboslute Gain (loss) M-o-M (in Cr) | J2: % Change (M-o-M) | K2: Benchmark Performance | L2: Index Benchmarked | O2: 46203 | P2: 46171 | Q2: % Change | R2: 45911 | S2: % Change | T2: 45933 | U2: % Change
C3: Managed Equity | D3: =SUM(D4:D12) -> 714.11115 | E3: =SUM(E4:E12) -> 32.499625 | F3: =SUM(F4:F12) -> 24.877565 | G3: =SUM(G4:G12) -> 0.00195 | H3: =SUM(H4:H12) -> 759.42288 | I3: =H3+G3+F3-E3-D3 -> 37.691628 | J3: =((H3+G3+F3)/(E3+D3))-1 -> 0.050483639 | K3: =SUMPRODUCT(K4:K12,H4:H12)/SUM(H4:H12) -> 0.018400797 | N3: Nifty 500 TRI | O3: 36880.75 | P3: 36261.8 | Q3: =(O3-P3)/P3 -> 0.017068927 | R3: 23102.65 | S3: =(R3-O3)/O3 -> -0.37358514 | T3: 23027.7 | U3: =(T3-R3)/R3 -> -0.0032442166
B4: * | C4: Direct Equity - MO | D4: 23.147697 | E4: =SUMIFS(Transactions!L:L,Transactions!J:J,'Month on Month Equity Change'!C4) -> 0 | F4: =SUMIFS(Transactions!F:F,Transactions!D:D,'Month on Month Equity Change'!C4) -> 0 | H4: =VLOOKUP(C4,'Live Equity Performance'!$B$7:$F$15,5,0) -> 21.640258 | I4: =H4+F4+G4-E4-D4 -> -1.5074395 | J4: =((H4+G4+F4)/(E4+D4))-1 -> -0.065122655 | K4: =Q3 -> 0.017068927 | L4: =$N$3 -> Nifty 500 TRI | N4: Nifty 50 TRI | O4: 36145.88 | P4: 35552.64 | Q4: =(O4-P4)/P4 -> 0.016686243 | R4: 25005.5 | S4: =(R4-O4)/O4 -> -0.30820608 | T4: 24894.25 | U4: =(T4-R4)/R4 -> -0.0044490212
C5: Direct Equity - Unlisted | D5: 62.828516 | E5: =SUMIFS(Transactions!L:L,Transactions!J:J,'Month on Month Equity Change'!C5) -> 0 | F5: =SUMIFS(Transactions!F:F,Transactions!D:D,'Month on Month Equity Change'!C5) -> 0 | H5: =VLOOKUP(C5,'Live Equity Performance'!$B$7:$F$15,5,0) -> 64.328516 | I5: =H5+F5+G5-E5-D5 -> 1.5 | J5: =((H5+G5+F5)/(E5+D5))-1 -> 0.02387451 | K5: =Q4 -> 0.016686243 | L5: =$N$3 -> Nifty 500 TRI | N5: Nifty Next 50 | O5: 71629.45 | P5: 71073.65 | Q5: =(O5-P5)/P5 -> 0.0078200571 | R5: 67974.7 | S5: =(R5-O5)/O5 -> -0.051023008 | T5: 68355.9 | U5: =(T5-R5)/R5 -> 0.0056079688
C6: LKP Sec Portfolio | D6: 0.8976215 | E6: =SUMIFS(Transactions!L:L,Transactions!J:J,'Month on Month Equity Change'!C6) -> 0 | F6: =SUMIFS(Transactions!F:F,Transactions!D:D,'Month on Month Equity Change'!C6) -> 0.3055521 | G6: ='Portfolio Allocation'!J15 -> 0.00195 | H6: =VLOOKUP(C6,'Live Equity Performance'!$B$7:$F$15,5,0) -> 0.84977725 | I6: =H6+F6+G6-E6-D6 -> 0.25965785 | J6: =((H6+G6+F6)/(E6+D6))-1 -> 0.28927321 | K6: =Q11 -> 0.021063079 | L6: Nifty Mid & Smallcap 400 TR
C7: Multi Cap | D7: 332.0286 | E7: =SUMIFS(Transactions!L:L,Transactions!J:J,'Month on Month Equity Change'!C7) -> 32.499625 | F7: =SUMIFS(Transactions!F:F,Transactions!D:D,'Month on Month Equity Change'!C7) -> 15.53989 | H7: =VLOOKUP(C7,'Live Equity Performance'!$B$7:$F$15,5,0) -> 361.70793 | I7: =H7+F7+G7-E7-D7 -> 12.719603 | J7: =((H7+G7+F7)/(E7+D7))-1 -> 0.03489333 | K7: =Q3 -> 0.017068927 | L7: =$N$3 -> Nifty 500 TRI | N7: Balanced Index | O7: 21017.898 | P7: 20658.15 | Q7: =(O7-P7)/P7 -> 0.017414367 | R7: 20787.813 | S7: =(R7-O7)/O7 -> -0.010947122 | T7: 20786.171 | U7: =(T7-R7)/R7 -> -7.8998209e-05
C8: Equity Hybrid | D8: 70.26721 | E8: =SUMIFS(Transactions!L:L,Transactions!J:J,'Month on Month Equity Change'!C8) -> 0 | F8: =SUMIFS(Transactions!F:F,Transactions!D:D,'Month on Month Equity Change'!C8)-4.31 -> 9.0321225 | H8: ='Attribution Analysis'!B25 -> 62.768957 | I8: =H8+F8+G8-E8-D8 -> 1.5338696 | J8: ='Attribution Analysis'!F25 -> 0.021823773 | K8: =Q7 -> 0.017414367 | L8: Balanced Index | N8: Nifty Midcap 150 TR | O8: 29049.9 | P8: 28766.84 | Q8: =(O8-P8)/P8 -> 0.0098398017 | R8: 27323.85 | S8: =(R8-O8)/O8 -> -0.059416728 | T8: 27191.96 | U8: =(T8-R8)/R8 -> -0.0048269186
B9: * | C9: Mid & Small Cap | D9: 223.51739 | E9: =SUMIFS(Transactions!L:L,Transactions!J:J,'Month on Month Equity Change'!C9) -> 0 | F9: =SUMIFS(Transactions!F:F,Transactions!D:D,'Month on Month Equity Change'!C9) -> 0 | H9: =VLOOKUP(C9,'Live Equity Performance'!$B$7:$F$15,5,0) -> 246.75783 | I9: =H9+F9+G9-E9-D9 -> 23.240438 | J9: =((H9+G9+F9)/(E9+D9))-1 -> 0.10397597 | K9: =Q11 -> 0.021063079 | L9: Nifty Mid & Smallcap 400 TR | N9: Nifty Smallcap 250 TR | O9: 22573.38 | P9: 21635.09 | Q9: =(O9-P9)/P9 -> 0.043368897 | R9: 21706.21 | S9: =(R9-O9)/O9 -> -0.038415603 | T9: 21614.49 | U9: =(T9-R9)/R9 -> -0.0042255189
C10: Small Cap | D10: 1.1531672 | E10: =SUMIFS(Transactions!L:L,Transactions!J:J,'Month on Month Equity Change'!C10) -> 0 | F10: =SUMIFS(Transactions!F:F,Transactions!D:D,'Month on Month Equity Change'!C10) -> 0 | H10: =VLOOKUP(C10,'Live Equity Performance'!$B$7:$F$15,5,0) -> 1.1248249 | I10: =H10+F10+G10-E10-D10 -> -0.0283423 | J10: =((H10+G10+F10)/(E10+D10))-1 -> -0.024577789 | K10: =Q9 -> 0.043368897 | L10: Nifty Small Cap | N10: Nifty Bank TR | O10: 80622.93 | P10: 75764.06 | Q10: =(O10-P10)/P10 -> 0.064131595 | R10: 76239.59 | S10: =(R10-O10)/O10 -> -0.054368404 | T10: 77522.14 | U10: =(T10-R10)/R10 -> 0.016822625
C11: Long-Short Fund | D11: - | E11: =SUMIFS(Transactions!L:L,Transactions!J:J,'Month on Month Equity Change'!C11) -> 0 | F11: =SUMIFS(Transactions!F:F,Transactions!D:D,'Month on Month Equity Change'!C11) -> 0 | H11: - | I11: - | J11: - | K11: =Q3 -> 0.017068927 | L11: =$N$3 -> Nifty 500 TRI | N11: Nifty Mid & Smallcap 400 TR | O11: 26687.25 | P11: 26136.73 | Q11: =(O11-P11)/P11 -> 0.021063079 | R11: 25311.39 | S11: =(R11-O11)/O11 -> -0.051554956 | T11: 25194.89 | U11: =(T11-R11)/R11 -> -0.004602671
C12: SLBM | D12: 0.27094463 | E12: =SUMIFS(Transactions!L:L,Transactions!J:J,'Month on Month Equity Change'!C12) -> 0 | F12: =SUMIFS(Transactions!F:F,Transactions!D:D,'Month on Month Equity Change'!C12) -> 0 | H12: =VLOOKUP(C12,'Live Equity Performance'!$B$7:$F$15,5,0) -> 0.24478595
C13: Direct Equity - Personal | D13: =D14 -> 202.82711 | E13: =SUM(E14:E14) -> 1.8894636 | F13: =SUM(F14:F14) -> 3.000036 | G13: =SUM(G14:G14) -> 1.8273252 | H13: =SUM(H14:H14) -> 222.35865 | I13: =SUM(I14:I14) -> 22.46944 | J13: =((H13+G13+F13)/(E13+D13))-1 -> 0.10975877 | K13: =K14 -> 0.021063079
C14: Direct Equity - Non MO | D14: 202.82711 | E14: =SUMIFS(Transactions!L:L,Transactions!J:J,'Month on Month Equity Change'!C14) -> 1.8894636 | F14: =SUMIFS(Transactions!F:F,Transactions!D:D,'Month on Month Equity Change'!C14) -> 3.000036 | G14: ='Portfolio Allocation'!J9 -> 1.8273252 | H14: =VLOOKUP(C14,'Live Equity Performance'!$B$7:$F$14,5,0) -> 222.35865 | I14: =H14+G14+F14-E14-D14 -> 22.46944 | J14: =((H14+G14+F14)/(E14+D14))-1 -> 0.10975877 | K14: =Q11 -> 0.021063079 | L14: Nifty Mid & Smallcap 400 TR
B15: * | C15: Total | D15: =D13+D3 -> 916.93825 | E15: =E13+E3 -> 34.389089 | F15: =F13+F3 -> 27.877601 | G15: =G13+G3 -> 1.8292752 | H15: =H13+H3 -> 981.78153 | I15: =H15+G15+F15-E15-D15 -> 60.161068 | J15: =((H15+G15+F15)/(E15+D15))-1 -> 0.063239083 | K15: =K3*(H3/H15)+K13*(H13/H15) -> 0.019003763
C16: Managed - Excl Unlisted | D16: =D3-D5 -> 651.28263 | E16: =E3-E5 -> 32.499625 | F16: =F3-F5 -> 24.877565 | G16: =G3-G5 -> 0.00195 | H16: =H3-H5 -> 695.09437 | I16: =H16+G16+F16-E16-D16 -> 36.191628 | J16: =((H16+G16+F16)/(E16+D16))-1 -> 0.052928587 | K16: =K3*((H3-H5)/(H15-H5))+K13*((H13)/(H15-H5)) -> 0.019046041
C17: Note: Direct Equity - Unlisted includes NSE and Zepto
C18: Note: Direct Equity MO includes Onesource and Kaynes Technology
C19: Note: Any incremental sale/ purchase after 30th April has been shown in the analysis , transactions upto 30th April have been captured under previous month market value
C20: *Equity Savings & Multi Asset excluded from equity hybrid

Sheet Equity Quants
B1: As on 30th June 2026
B2: Top 20 Stocks | C2: Allocation in % | D2: No of Schemes in | E2: Nifty 50 Allocation | F2: Nifty 500 Allocation | H2: Top 10 Sectors | I2: Allocation in Portfolio | J2: Allocation in Nifty 50 | K2: Allocation in Nifty 500
