Workbook

Sheet Start Here
B1: Consolidated Client Data Template
B2: One workbook for any client's portfolio: the registers hold the data in one standard shape, the views present it the way the family reads it.
B3: DEMO DATA — illustrative only: a fictional family, fictional securities and figures.
B5: SETTINGS
B6: Client / family name | C6: Malhotra Family Office (DEMO) | D6: Printed at the top of every view.
B7: Valuation date | C7: 46203 | D7: The date the market values are struck at.
B8: Previous valuation date | C8: 46112 | D8: Start of the window the Period Change view measures.
B9: Show figures in | C9: ₹ Crore | D9: ₹ Crore, ₹ Lakh or ₹. The registers always hold full rupees.
B10: Divide ₹ by | C10: =IFERROR(INDEX(L_UnitDiv,MATCH(UnitLabel,L_Unit,0)),1) -> 10000000 | D10: Set by 'Show figures in'; every view divides by it.
B11: Grandfathering date (s.112A) | C11: 43131 | D11: Listed equity bought on or before this date is taxed from its FMV on this date.
B12: Overall status | C12: =OverallStatus -> ALL CHECKS PASS · 6 note(s) to read | D12: =HYPERLINK("#'Checks'!A1","Open the Checks sheet →") -> Open the Checks sheet →
B14: WHAT IS IN THIS WORKBOOK — click a name to open it
B15: =HYPERLINK("#'Portfolio Allocation'!A1","Portfolio Allocation") -> Portfolio Allocation | C15: View | D15: What the family owns by asset class and category: cost, value, allocation, gains and returns against the benchmark.
B16: =HYPERLINK("#'Basket Allocation'!A1","Basket Allocation") -> Basket Allocation | C16: View | D16: Stable Growth, Entrepreneurial Growth, Liquidity, Thematic & Tactical against the family's targets.
B17: =HYPERLINK("#'Basket Detail'!A1","Basket Detail") -> Basket Detail | C17: View | D17: Every holding in each basket, largest first, with its return.
B18: =HYPERLINK("#'Investor Summary'!A1","Investor Summary") -> Investor Summary | C18: View | D18: Each entity's money by category, and its share of that entity's portfolio.
B19: =HYPERLINK("#'Period Change'!A1","Period Change") -> Period Change | C19: View | D19: What moved since the previous valuation date: invested, redeemed, market gain, income.
B20: =HYPERLINK("#'Tax Summary'!A1","Tax Summary") -> Tax Summary | C20: View | D20: Capital gains by taxpayer: book and taxable, long- and short-term, grandfathered; lots about to turn long-term.
B21: =HYPERLINK("#'Checks'!A1","Checks") -> Checks | C21: Check | D21: Does everything tie? Every view against the registers, every row check.
B22: =HYPERLINK("#'Holdings'!A1","Holdings") -> Holdings | C22: Register | D22: One row per security per account: the position the views are built from.
B23: =HYPERLINK("#'Tax Lots'!A1","Tax Lots") -> Tax Lots | C23: Register | D23: One row per purchase lot: purchase, sale, grandfathering, taxable gain.
B24: =HYPERLINK("#'Transactions'!A1","Transactions") -> Transactions | C24: Register | D24: Dated money movements: buys, sells, SIPs, calls, distributions, income.
B25: =HYPERLINK("#'Commitments'!A1","Commitments") -> Commitments | C25: Register | D25: Money promised to AIFs and private deals: committed, called, paid, uncalled, TVPI.
B26: =HYPERLINK("#'Entities'!A1","Entities") -> Entities | C26: Master data | D26: The family's taxpayers.
B27: =HYPERLINK("#'Accounts'!A1","Accounts") -> Accounts | C27: Master data | D27: Where each holding sits, and the date of each provider's statement.
B28: =HYPERLINK("#'Securities'!A1","Securities") -> Securities | C28: Master data | D28: What each holding is: category, basket, benchmark, price.
B29: =HYPERLINK("#'Lists'!A1","Lists") -> Lists | C29: Reference | D29: The standard classification and every dropdown's values.
B30: =HYPERLINK("#'Column Mapping'!A1","Column Mapping") -> Column Mapping | C30: Reference | D30: Where each column comes from in the two source formats, and how to convert it.
B32: HOW TO READ A SHEET
B33: Typed value | C33: Yellow cell, blue text: a figure or choice someone types.
B34: Calculated | C34: Grey cell, black text: a formula. Do not type over it.
B35: Header | C35: Navy: column names. Gold rows on the views are group totals.
B36: Row check | C36: Red when a row has a problem; green OK when it ties.
B38: HOW TO LOAD A NEW CLIENT
B39: Step 1 | C39: Set the client name, the valuation date and the previous valuation date above.
B40: Step 2 | C40: Entities: one row per taxpayer. Accounts: one row per demat, PMS, folio, bank account or platform, with its statement date.
B41: Step 3 | C41: Securities: one row per security or scheme. Pick its category from the dropdown — that sets asset class, basket and benchmark. Type the price at the valuation date.
B42: Step 4 | C42: Holdings: one row per security per account. Type quantity and invested cost; the market value is quantity × price (or type the statement value in the override column).
B43: Step 5 | C43: Tax Lots (listed shares and funds): one row per purchase lot, with any sale against it. Leave quantity, cost and realised gain on Holdings equal to the lots' totals.
B44: Step 6 | C44: Transactions: every dated flow since the previous valuation date, at least. Commitments: every AIF or private deal with a drawdown.
...

Sheet Portfolio Allocation
A1: ="Portfolio Allocation — "&ClientName -> Portfolio Allocation — Malhotra Family Office (DEMO) | T1: =HYPERLINK("#'Start Here'!A1","← Start Here") -> ← Start Here
A2: ="Figures in "&UnitLabel&" · market values as at "&TEXT(ValDate,"dd-mmm-yyyy") -> Figures in ₹ Crore · market values as at 30-Jun-2026
A3: DEMO DATA — illustrative only: a fictional family, fictional securities and figures.
B5: Category | C5: Investment date range | D5: Investment at cost | E5: Market value | F5: Allocation (% of portfolio) | G5: Allocation (% of asset class) | I5: Dividend / interest | K5: Gain / (loss) including redeemed | M5: Gain / (loss) on what is held | O5: Absolute return (%) | R5: Annualised return — XIRR (%)
O6: Portfolio | P6: Blended index | R6: Portfolio | S6: Blended index | T6: Share of value covered
B7: =Lists!$A$6 -> Equity | C7: =IF(COUNTIFS(Holdings!$G$6:$G$205,$B7,Holdings!$J$6:$J$205,">0")=0,"",TEXT(_xlfn.MINIFS(Holdings!$J$6:$J$205,Holdings!$G$6:$G$205,$B7),"mmm-yy")&" – "&TEXT(MAX(_xlfn.MAXIFS(Holdings!$J$6:$J$205,Holdings!$G$6:$G$205,$B7),_xlfn.MAXIFS(Holdings!$K$6:$K$205,Holdings!$G$6:$G$205,$B7)),"mmm-yy")) -> Mar-16 – Jun-26 | D7: =SUMIFS(Holdings!$M$6:$M$205,Holdings!$G$6:$G$205,$B7)/Divisor -> 59.67793 | E7: =SUMIFS(Holdings!$R$6:$R$205,Holdings!$G$6:$G$205,$B7)/Divisor -> 84.35414 | F7: =IF(N($E$31)=0,"",E7/$E$31) -> 0.60916718 | I7: =SUMIFS(Holdings!$U$6:$U$205,Holdings!$G$6:$G$205,$B7)/Divisor -> 0.415 | K7: =(SUMIFS(Holdings!$V$6:$V$205,Holdings!$G$6:$G$205,$B7)+SUMIFS(Holdings!$S$6:$S$205,Holdings!$G$6:$G$205,$B7))/Divisor -> 29.07521 | M7: =SUMIFS(Holdings!$S$6:$S$205,Holdings!$G$6:$G$205,$B7)/Divisor -> 24.67621 | O7: =IF(N(D7)=0,"",M7/D7) -> 0.41348971 | P7: =IF(SUMIFS(Holdings!$AQ$6:$AQ$205,Holdings!$G$6:$G$205,$B7)=0,"",SUMIFS(Holdings!$AP$6:$AP$205,Holdings!$G$6:$G$205,$B7)/SUMIFS(Holdings!$AQ$6:$AQ$205,Holdings!$G$6:$G$205,$B7)) -> 0.50594734 | R7: =IF(SUMIFS(Holdings!$AN$6:$AN$205,Holdings!$G$6:$G$205,$B7)=0,"",SUMIFS(Holdings!$AM$6:$AM$205,Holdings!$G$6:$G$205,$B7)/SUMIFS(Holdings!$AN$6:$AN$205,Holdings!$G$6:$G$205,$B7)) -> 0.14574724 | S7: =IF(SUMIFS(Holdings!$AN$6:$AN$205,Holdings!$G$6:$G$205,$B7)=0,"",SUMIFS(Holdings!$AO$6:$AO$205,Holdings!$G$6:$G$205,$B7)/SUMIFS(Holdings!$AN$6:$AN$205,Holdings!$G$6:$G$205,$B7)) -> 0.13020211 | T7: =IF(N(E7)=0,"",SUMIFS(Holdings!$AN$6:$AN$205,Holdings!$G$6:$G$205,$B7)/Divisor/E7) -> 0.92837909
B8: =Lists!$D$6 -> Direct Equity | C8: =IF(COUNTIFS(Holdings!$H$6:$H$205,$B8,Holdings!$J$6:$J$205,">0")=0,"",TEXT(_xlfn.MINIFS(Holdings!$J$6:$J$205,Holdings!$H$6:$H$205,$B8),"mmm-yy")&" – "&TEXT(MAX(_xlfn.MAXIFS(Holdings!$J$6:$J$205,Holdings!$H$6:$H$205,$B8),_xlfn.MAXIFS(Holdings!$K$6:$K$205,Holdings!$H$6:$H$205,$B8)),"mmm-yy")) -> Mar-16 – Feb-26 | D8: =SUMIFS(Holdings!$M$6:$M$205,Holdings!$H$6:$H$205,$B8)/Divisor -> 18.38913 | E8: =SUMIFS(Holdings!$R$6:$R$205,Holdings!$H$6:$H$205,$B8)/Divisor -> 26.036545 | F8: =IF(N($E$31)=0,"",E8/$E$31) -> 0.18802407 | G8: =IF(N($E$7)=0,"",E8/$E$7) -> 0.30865758 | I8: =SUMIFS(Holdings!$U$6:$U$205,Holdings!$H$6:$H$205,$B8)/Divisor -> 0.303 | K8: =(SUMIFS(Holdings!$V$6:$V$205,Holdings!$H$6:$H$205,$B8)+SUMIFS(Holdings!$S$6:$S$205,Holdings!$H$6:$H$205,$B8))/Divisor -> 10.081415 | M8: =SUMIFS(Holdings!$S$6:$S$205,Holdings!$H$6:$H$205,$B8)/Divisor -> 7.647415 | O8: =IF(N(D8)=0,"",M8/D8) -> 0.41586606 | P8: =IF(SUMIFS(Holdings!$AQ$6:$AQ$205,Holdings!$H$6:$H$205,$B8)=0,"",SUMIFS(Holdings!$AP$6:$AP$205,Holdings!$H$6:$H$205,$B8)/SUMIFS(Holdings!$AQ$6:$AQ$205,Holdings!$H$6:$H$205,$B8)) -> 0.57144073 | R8: =IF(SUMIFS(Holdings!$AN$6:$AN$205,Holdings!$H$6:$H$205,$B8)=0,"",SUMIFS(Holdings!$AM$6:$AM$205,Holdings!$H$6:$H$205,$B8)/SUMIFS(Holdings!$AN$6:$AN$205,Holdings!$H$6:$H$205,$B8)) -> 0.11957614 | S8: =IF(SUMIFS(Holdings!$AN$6:$AN$205,Holdings!$H$6:$H$205,$B8)=0,"",SUMIFS(Holdings!$AO$6:$AO$205,Holdings!$H$6:$H$205,$B8)/SUMIFS(Holdings!$AN$6:$AN$205,Holdings!$H$6:$H$205,$B8)) -> 0.12442964 | T8: =IF(N(E8)=0,"",SUMIFS(Holdings!$AN$6:$AN$205,Holdings!$H$6:$H$205,$B8)/Divisor/E8) -> 0.76796
B9: =Lists!$D$7 -> Equity MF – Large / Flexi / Multi Cap | C9: =IF(COUNTIFS(Holdings!$H$6:$H$205,$B9,Holdings!$J$6:$J$205,">0")=0,"",TEXT(_xlfn.MINIFS(Holdings!$J$6:$J$205,Holdings!$H$6:$H$205,$B9),"mmm-yy")&" – "&TEXT(MAX(_xlfn.MAXIFS(Holdings!$J$6:$J$205,Holdings!$H$6:$H$205,$B9),_xlfn.MAXIFS(Holdings!$K$6:$K$205,Holdings!$H$6:$H$205,$B9)),"mmm-yy")) -> Jan-18 – Jan-18 | D9: =SUMIFS(Holdings!$M$6:$M$205,Holdings!$H$6:$H$205,$B9)/Divisor -> 3.84 | E9: =SUMIFS(Holdings!$R$6:$R$205,Holdings!$H$6:$H$205,$B9)/Divisor -> 9.64312 | F9: =IF(N($E$31)=0,"",E9/$E$31) -> 0.069638221 | G9: =IF(N($E$7)=0,"",E9/$E$7) -> 0.11431709 | I9: =SUMIFS(Holdings!$U$6:$U$205,Holdings!$H$6:$H$205,$B9)/Divisor -> 0 | K9: =(SUMIFS(Holdings!$V$6:$V$205,Holdings!$H$6:$H$205,$B9)+SUMIFS(Holdings!$S$6:$S$205,Holdings!$H$6:$H$205,$B9))/Divisor -> 7.12312 | M9: =SUMIFS(Holdings!$S$6:$S$205,Holdings!$H$6:$H$205,$B9)/Divisor -> 5.80312 | O9: =IF(N(D9)=0,"",M9/D9) -> 1.5112292 | P9: =IF(SUMIFS(Holdings!$AQ$6:$AQ$205,Holdings!$H$6:$H$205,$B9)=0,"",SUMIFS(Holdings!$AP$6:$AP$205,Holdings!$H$6:$H$205,$B9)/SUMIFS(Holdings!$AQ$6:$AQ$205,Holdings!$H$6:$H$205,$B9)) -> 1.318 | R9: =IF(SUMIFS(Holdings!$AN$6:$AN$205,Holdings!$H$6:$H$205,$B9)=0,"",SUMIFS(Holdings!$AM$6:$AM$205,Holdings!$H$6:$H$205,$B9)/SUMIFS(Holdings!$AN$6:$AN$205,Holdings!$H$6:$H$205,$B9)) -> 0.112 | S9: =IF(SUMIFS(Holdings!$AN$6:$AN$205,Holdings!$H$6:$H$205,$B9)=0,"",SUMIFS(Holdings!$AO$6:$AO$205,Holdings!$H$6:$H$205,$B9)/SUMIFS(Holdings!$AN$6:$AN$205,Holdings!$H$6:$H$205,$B9)) -> 0.126 | T9: =IF(N(E9)=0,"",SUMIFS(Holdings!$AN$6:$AN$205,Holdings!$H$6:$H$205,$B9)/Divisor/E9) -> 1
B10: =Lists!$D$8 -> Equity MF – Mid & Small Cap | C10: =IF(COUNTIFS(Holdings!$H$6:$H$205,$B10,Holdings!$J$6:$J$205,">0")=0,"",TEXT(_xlfn.MINIFS(Holdings!$J$6:$J$205,Holdings!$H$6:$H$205,$B10),"mmm-yy")&" – "&TEXT(MAX(_xlfn.MAXIFS(Holdings!$J$6:$J$205,Holdings!$H$6:$H$205,$B10),_xlfn.MAXIFS(Holdings!$K$6:$K$205,Holdings!$H$6:$H$205,$B10)),"mmm-yy")) -> Apr-23 – Jun-26 | D10: =SUMIFS(Holdings!$M$6:$M$205,Holdings!$H$6:$H$205,$B10)/Divisor -> 4.25 | E10: =SUMIFS(Holdings!$R$6:$R$205,Holdings!$H$6:$H$205,$B10)/Divisor -> 5.8950699 | F10: =IF(N($E$31)=0,"",E10/$E$31) -> 0.04257151 | G10: =IF(N($E$7)=0,"",E10/$E$7) -> 0.069884772 | I10: =SUMIFS(Holdings!$U$6:$U$205,Holdings!$H$6:$H$205,$B10)/Divisor -> 0 | K10: =(SUMIFS(Holdings!$V$6:$V$205,Holdings!$H$6:$H$205,$B10)+SUMIFS(Holdings!$S$6:$S$205,Holdings!$H$6:$H$205,$B10))/Divisor -> 1.6450699 | M10: =SUMIFS(Holdings!$S$6:$S$205,Holdings!$H$6:$H$205,$B10)/Divisor -> 1.6450699 | O10: =IF(N(D10)=0,"",M10/D10) -> 0.38707526 | P10: =IF(SUMIFS(Holdings!$AQ$6:$AQ$205,Holdings!$H$6:$H$205,$B10)=0,"",SUMIFS(Holdings!$AP$6:$AP$205,Holdings!$H$6:$H$205,$B10)/SUMIFS(Holdings!$AQ$6:$AQ$205,Holdings!$H$6:$H$205,$B10)) -> 0.362 | R10: =IF(SUMIFS(Holdings!$AN$6:$AN$205,Holdings!$H$6:$H$205,$B10)=0,"",SUMIFS(Holdings!$AM$6:$AM$205,Holdings!$H$6:$H$205,$B10)/SUMIFS(Holdings!$AN$6:$AN$205,Holdings!$H$6:$H$205,$B10)) -> 0.214 | S10: =IF(SUMIFS(Holdings!$AN$6:$AN$205,Holdings!$H$6:$H$205,$B10)=0,"",SUMIFS(Holdings!$AO$6:$AO$205,Holdings!$H$6:$H$205,$B10)/SUMIFS(Holdings!$AN$6:$AN$205,Holdings!$H$6:$H$205,$B10)) -> 0.189 | T10: =IF(N(E10)=0,"",SUMIFS(Holdings!$AN$6:$AN$205,Holdings!$H$6:$H$205,$B10)/Divisor/E10) -> 1
B11: =Lists!$D$9 -> Equity MF – Hybrid / BAF | C11: =IF(COUNTIFS(Holdings!$H$6:$H$205,$B11,Holdings!$J$6:$J$205,">0")=0,"",TEXT(_xlfn.MINIFS(Holdings!$J$6:$J$205,Holdings!$H$6:$H$205,$B11),"mmm-yy")&" – "&TEXT(MAX(_xlfn.MAXIFS(Holdings!$J$6:$J$205,Holdings!$H$6:$H$205,$B11),_xlfn.MAXIFS(Holdings!$K$6:$K$205,Holdings!$H$6:$H$205,$B11)),"mmm-yy")) -> Oct-23 – Oct-23 | D11: =SUMIFS(Holdings!$M$6:$M$205,Holdings!$H$6:$H$205,$B11)/Divisor -> 3.5 | E11: =SUMIFS(Holdings!$R$6:$R$205,Holdings!$H$6:$H$205,$B11)/Divisor -> 4.013205 | F11: =IF(N($E$31)=0,"",E11/$E$31) -> 0.028981539 | G11: =IF(N($E$7)=0,"",E11/$E$7) -> 0.047575673 | I11: =SUMIFS(Holdings!$U$6:$U$205,Holdings!$H$6:$H$205,$B11)/Divisor -> 0 | K11: =(SUMIFS(Holdings!$V$6:$V$205,Holdings!$H$6:$H$205,$B11)+SUMIFS(Holdings!$S$6:$S$205,Holdings!$H$6:$H$205,$B11))/Divisor -> 0.513205 | M11: =SUMIFS(Holdings!$S$6:$S$205,Holdings!$H$6:$H$205,$B11)/Divisor -> 0.513205 | O11: =IF(N(D11)=0,"",M11/D11) -> 0.14663 | P11: =IF(SUMIFS(Holdings!$AQ$6:$AQ$205,Holdings!$H$6:$H$205,$B11)=0,"",SUMIFS(Holdings!$AP$6:$AP$205,Holdings!$H$6:$H$205,$B11)/SUMIFS(Holdings!$AQ$6:$AQ$205,Holdings!$H$6:$H$205,$B11)) -> 0.241 | R11: =IF(SUMIFS(Holdings!$AN$6:$AN$205,Holdings!$H$6:$H$205,$B11)=0,"",SUMIFS(Holdings!$AM$6:$AM$205,Holdings!$H$6:$H$205,$B11)/SUMIFS(Holdings!$AN$6:$AN$205,Holdings!$H$6:$H$205,$B11)) -> 0.108 | S11: =IF(SUMIFS(Holdings!$AN$6:$AN$205,Holdings!$H$6:$H$205,$B11)=0,"",SUMIFS(Holdings!$AO$6:$AO$205,Holdings!$H$6:$H$205,$B11)/SUMIFS(Holdings!$AN$6:$AN$205,Holdings!$H$6:$H$205,$B11)) -> 0.115 | T11: =IF(N(E11)=0,"",SUMIFS(Holdings!$AN$6:$AN$205,Holdings!$H$6:$H$205,$B11)/Divisor/E11) -> 1
B12: =Lists!$D$10 -> Equity ETF / Index Fund | C12: =IF(COUNTIFS(Holdings!$H$6:$H$205,$B12,Holdings!$J$6:$J$205,">0")=0,"",TEXT(_xlfn.MINIFS(Holdings!$J$6:$J$205,Holdings!$H$6:$H$205,$B12),"mmm-yy")&" – "&TEXT(MAX(_xlfn.MAXIFS(Holdings!$J$6:$J$205,Holdings!$H$6:$H$205,$B12),_xlfn.MAXIFS(Holdings!$K$6:$K$205,Holdings!$H$6:$H$205,$B12)),"mmm-yy")) | D12: =SUMIFS(Holdings!$M$6:$M$205,Holdings!$H$6:$H$205,$B12)/Divisor -> 0 | E12: =SUMIFS(Holdings!$R$6:$R$205,Holdings!$H$6:$H$205,$B12)/Divisor -> 0 | F12: =IF(N($E$31)=0,"",E12/$E$31) -> 0 | G12: =IF(N($E$7)=0,"",E12/$E$7) -> 0 | I12: =SUMIFS(Holdings!$U$6:$U$205,Holdings!$H$6:$H$205,$B12)/Divisor -> 0 | K12: =(SUMIFS(Holdings!$V$6:$V$205,Holdings!$H$6:$H$205,$B12)+SUMIFS(Holdings!$S$6:$S$205,Holdings!$H$6:$H$205,$B12))/Divisor -> 0 | M12: =SUMIFS(Holdings!$S$6:$S$205,Holdings!$H$6:$H$205,$B12)/Divisor -> 0 | O12: =IF(N(D12)=0,"",M12/D12) | P12: =IF(SUMIFS(Holdings!$AQ$6:$AQ$205,Holdings!$H$6:$H$205,$B12)=0,"",SUMIFS(Holdings!$AP$6:$AP$205,Holdings!$H$6:$H$205,$B12)/SUMIFS(Holdings!$AQ$6:$AQ$205,Holdings!$H$6:$H$205,$B12)) | R12: =IF(SUMIFS(Holdings!$AN$6:$AN$205,Holdings!$H$6:$H$205,$B12)=0,"",SUMIFS(Holdings!$AM$6:$AM$205,Holdings!$H$6:$H$205,$B12)/SUMIFS(Holdings!$AN$6:$AN$205,Holdings!$H$6:$H$205,$B12)) | S12: =IF(SUMIFS(Holdings!$AN$6:$AN$205,Holdings!$H$6:$H$205,$B12)=0,"",SUMIFS(Holdings!$AO$6:$AO$205,Holdings!$H$6:$H$205,$B12)/SUMIFS(Holdings!$AN$6:$AN$205,Holdings!$H$6:$H$205,$B12)) | T12: =IF(N(E12)=0,"",SUMIFS(Holdings!$AN$6:$AN$205,Holdings!$H$6:$H$205,$B12)/Divisor/E12)
B13: =Lists!$D$11 -> PMS – Equity | C13: =IF(COUNTIFS(Holdings!$H$6:$H$205,$B13,Holdings!$J$6:$J$205,">0")=0,"",TEXT(_xlfn.MINIFS(Holdings!$J$6:$J$205,Holdings!$H$6:$H$205,$B13),"mmm-yy")&" – "&TEXT(MAX(_xlfn.MAXIFS(Holdings!$J$6:$J$205,Holdings!$H$6:$H$205,$B13),_xlfn.MAXIFS(Holdings!$K$6:$K$205,Holdings!$H$6:$H$205,$B13)),"mmm-yy")) -> Apr-22 – Jan-25 | D13: =SUMIFS(Holdings!$M$6:$M$205,Holdings!$H$6:$H$205,$B13)/Divisor -> 15 | E13: =SUMIFS(Holdings!$R$6:$R$205,Holdings!$H$6:$H$205,$B13)/Divisor -> 18.124 | F13: =IF(N($E$31)=0,"",E13/$E$31) -> 0.13088327 | G13: =IF(N($E$7)=0,"",E13/$E$7) -> 0.21485608 | I13: =SUMIFS(Holdings!$U$6:$U$205,Holdings!$H$6:$H$205,$B13)/Divisor -> 0.112 | K13: =(SUMIFS(Holdings!$V$6:$V$205,Holdings!$H$6:$H$205,$B13)+SUMIFS(Holdings!$S$6:$S$205,Holdings!$H$6:$H$205,$B13))/Divisor -> 3.769 | M13: =SUMIFS(Holdings!$S$6:$S$205,Holdings!$H$6:$H$205,$B13)/Divisor -> 3.124 | O13: =IF(N(D13)=0,"",M13/D13) -> 0.20826667 | P13: =IF(SUMIFS(Holdings!$AQ$6:$AQ$205,Holdings!$H$6:$H$205,$B13)=0,"",SUMIFS(Holdings!$AP$6:$AP$205,Holdings!$H$6:$H$205,$B13)/SUMIFS(Holdings!$AQ$6:$AQ$205,Holdings!$H$6:$H$205,$B13)) -> 0.385 | R13: =IF(SUMIFS(Holdings!$AN$6:$AN$205,Holdings!$H$6:$H$205,$B13)=0,"",SUMIFS(Holdings!$AM$6:$AM$205,Holdings!$H$6:$H$205,$B13)/SUMIFS(Holdings!$AN$6:$AN$205,Holdings!$H$6:$H$205,$B13)) -> 0.142 | S13: =IF(SUMIFS(Holdings!$AN$6:$AN$205,Holdings!$H$6:$H$205,$B13)=0,"",SUMIFS(Holdings!$AO$6:$AO$205,Holdings!$H$6:$H$205,$B13)/SUMIFS(Holdings!$AN$6:$AN$205,Holdings!$H$6:$H$205,$B13)) -> 0.121 | T13: =IF(N(E13)=0,"",SUMIFS(Holdings!$AN$6:$AN$205,Holdings!$H$6:$H$205,$B13)/Divisor/E13) -> 1
B14: =Lists!$D$12 -> AIF Cat III – Listed Equity | C14: =IF(COUNTIFS(Holdings!$H$6:$H$205,$B14,Holdings!$J$6:$J$205,">0")=0,"",TEXT(_xlfn.MINIFS(Holdings!$J$6:$J$205,Holdings!$H$6:$H$205,$B14),"mmm-yy")&" – "&TEXT(MAX(_xlfn.MAXIFS(Holdings!$J$6:$J$205,Holdings!$H$6:$H$205,$B14),_xlfn.MAXIFS(Holdings!$K$6:$K$205,Holdings!$H$6:$H$205,$B14)),"mmm-yy")) -> Jan-23 – May-26 | D14: =SUMIFS(Holdings!$M$6:$M$205,Holdings!$H$6:$H$205,$B14)/Divisor -> 14.6988 | E14: =SUMIFS(Holdings!$R$6:$R$205,Holdings!$H$6:$H$205,$B14)/Divisor -> 20.6422 | F14: =IF(N($E$31)=0,"",E14/$E$31) -> 0.14906857 | G14: =IF(N($E$7)=0,"",E14/$E$7) -> 0.2447088 | I14: =SUMIFS(Holdings!$U$6:$U$205,Holdings!$H$6:$H$205,$B14)/Divisor -> 0 | K14: =(SUMIFS(Holdings!$V$6:$V$205,Holdings!$H$6:$H$205,$B14)+SUMIFS(Holdings!$S$6:$S$205,Holdings!$H$6:$H$205,$B14))/Divisor -> 5.9434 | M14: =SUMIFS(Holdings!$S$6:$S$205,Holdings!$H$6:$H$205,$B14)/Divisor -> 5.9434 | O14: =IF(N(D14)=0,"",M14/D14) -> 0.40434593 | P14: =IF(SUMIFS(Holdings!$AQ$6:$AQ$205,Holdings!$H$6:$H$205,$B14)=0,"",SUMIFS(Holdings!$AP$6:$AP$205,Holdings!$H$6:$H$205,$B14)/SUMIFS(Holdings!$AQ$6:$AQ$205,Holdings!$H$6:$H$205,$B14)) -> 0.44 | R14: =IF(SUMIFS(Holdings!$AN$6:$AN$205,Holdings!$H$6:$H$205,$B14)=0,"",SUMIFS(Holdings!$AM$6:$AM$205,Holdings!$H$6:$H$205,$B14)/SUMIFS(Holdings!$AN$6:$AN$205,Holdings!$H$6:$H$205,$B14)) -> 0.178 | S14: =IF(SUMIFS(Holdings!$AN$6:$AN$205,Holdings!$H$6:$H$205,$B14)=0,"",SUMIFS(Holdings!$AO$6:$AO$205,Holdings!$H$6:$H$205,$B14)/SUMIFS(Holdings!$AN$6:$AN$205,Holdings!$H$6:$H$205,$B14)) -> 0.132 | T14: =IF(N(E14)=0,"",SUMIFS(Holdings!$AN$6:$AN$205,Holdings!$H$6:$H$205,$B14)/Divisor/E14) -> 1
B15: =Lists!$A$7 -> Debt | C15: =IF(COUNTIFS(Holdings!$G$6:$G$205,$B15,Holdings!$J$6:$J$205,">0")=0,"",TEXT(_xlfn.MINIFS(Holdings!$J$6:$J$205,Holdings!$G$6:$G$205,$B15),"mmm-yy")&" – "&TEXT(MAX(_xlfn.MAXIFS(Holdings!$J$6:$J$205,Holdings!$G$6:$G$205,$B15),_xlfn.MAXIFS(Holdings!$K$6:$K$205,Holdings!$G$6:$G$205,$B15)),"mmm-yy")) -> Mar-24 – May-26 | D15: =SUMIFS(Holdings!$M$6:$M$205,Holdings!$G$6:$G$205,$B15)/Divisor -> 13 | E15: =SUMIFS(Holdings!$R$6:$R$205,Holdings!$G$6:$G$205,$B15)/Divisor -> 13.595184 | F15: =IF(N($E$31)=0,"",E15/$E$31) -> 0.098178228 | I15: =SUMIFS(Holdings!$U$6:$U$205,Holdings!$G$6:$G$205,$B15)/Divisor -> 0.43 | K15: =(SUMIFS(Holdings!$V$6:$V$205,Holdings!$G$6:$G$205,$B15)+SUMIFS(Holdings!$S$6:$S$205,Holdings!$G$6:$G$205,$B15))/Divisor -> 0.595184 | M15: =SUMIFS(Holdings!$S$6:$S$205,Holdings!$G$6:$G$205,$B15)/Divisor -> 0.595184 | O15: =IF(N(D15)=0,"",M15/D15) -> 0.045783385 | P15: =IF(SUMIFS(Holdings!$AQ$6:$AQ$205,Holdings!$G$6:$G$205,$B15)=0,"",SUMIFS(Holdings!$AP$6:$AP$205,Holdings!$G$6:$G$205,$B15)/SUMIFS(Holdings!$AQ$6:$AQ$205,Holdings!$G$6:$G$205,$B15)) -> 0.15638462 | R15: =IF(SUMIFS(Holdings!$AN$6:$AN$205,Holdings!$G$6:$G$205,$B15)=0,"",SUMIFS(Holdings!$AM$6:$AM$205,Holdings!$G$6:$G$205,$B15)/SUMIFS(Holdings!$AN$6:$AN$205,Holdings!$G$6:$G$205,$B15)) -> 0.083031223 | S15: =IF(SUMIFS(Holdings!$AN$6:$AN$205,Holdings!$G$6:$G$205,$B15)=0,"",SUMIFS(Holdings!$AO$6:$AO$205,Holdings!$G$6:$G$205,$B15)/SUMIFS(Holdings!$AN$6:$AN$205,Holdings!$G$6:$G$205,$B15)) -> 0.074806245 | T15: =IF(N(E15)=0,"",SUMIFS(Holdings!$AN$6:$AN$205,Holdings!$G$6:$G$205,$B15)/Divisor/E15) -> 0.92363472
B16: =Lists!$D$13 -> Debt MF | C16: =IF(COUNTIFS(Holdings!$H$6:$H$205,$B16,Holdings!$J$6:$J$205,">0")=0,"",TEXT(_xlfn.MINIFS(Holdings!$J$6:$J$205,Holdings!$H$6:$H$205,$B16),"mmm-yy")&" – "&TEXT(MAX(_xlfn.MAXIFS(Holdings!$J$6:$J$205,Holdings!$H$6:$H$205,$B16),_xlfn.MAXIFS(Holdings!$K$6:$K$205,Holdings!$H$6:$H$205,$B16)),"mmm-yy")) -> Jul-24 – Jul-24 | D16: =SUMIFS(Holdings!$M$6:$M$205,Holdings!$H$6:$H$205,$B16)/Divisor -> 7 | E16: =SUMIFS(Holdings!$R$6:$R$205,Holdings!$H$6:$H$205,$B16)/Divisor -> 7.494984 | F16: =IF(N($E$31)=0,"",E16/$E$31) -> 0.054125361 | G16: =IF(N($E$15)=0,"",E16/$E$15) -> 0.55129699 | I16: =SUMIFS(Holdings!$U$6:$U$205,Holdings!$H$6:$H$205,$B16)/Divisor -> 0 | K16: =(SUMIFS(Holdings!$V$6:$V$205,Holdings!$H$6:$H$205,$B16)+SUMIFS(Holdings!$S$6:$S$205,Holdings!$H$6:$H$205,$B16))/Divisor -> 0.494984 | M16: =SUMIFS(Holdings!$S$6:$S$205,Holdings!$H$6:$H$205,$B16)/Divisor -> 0.494984 | O16: =IF(N(D16)=0,"",M16/D16) -> 0.070712 | P16: =IF(SUMIFS(Holdings!$AQ$6:$AQ$205,Holdings!$H$6:$H$205,$B16)=0,"",SUMIFS(Holdings!$AP$6:$AP$205,Holdings!$H$6:$H$205,$B16)/SUMIFS(Holdings!$AQ$6:$AQ$205,Holdings!$H$6:$H$205,$B16)) -> 0.156 | R16: =IF(SUMIFS(Holdings!$AN$6:$AN$205,Holdings!$H$6:$H$205,$B16)=0,"",SUMIFS(Holdings!$AM$6:$AM$205,Holdings!$H$6:$H$205,$B16)/SUMIFS(Holdings!$AN$6:$AN$205,Holdings!$H$6:$H$205,$B16)) -> 0.079 | S16: =IF(SUMIFS(Holdings!$AN$6:$AN$205,Holdings!$H$6:$H$205,$B16)=0,"",SUMIFS(Holdings!$AO$6:$AO$205,Holdings!$H$6:$H$205,$B16)/SUMIFS(Holdings!$AN$6:$AN$205,Holdings!$H$6:$H$205,$B16)) -> 0.074 | T16: =IF(N(E16)=0,"",SUMIFS(Holdings!$AN$6:$AN$205,Holdings!$H$6:$H$205,$B16)/Divisor/E16) -> 1
B17: =Lists!$D$14 -> Bonds / NCDs | C17: =IF(COUNTIFS(Holdings!$H$6:$H$205,$B17,Holdings!$J$6:$J$205,">0")=0,"",TEXT(_xlfn.MINIFS(Holdings!$J$6:$J$205,Holdings!$H$6:$H$205,$B17),"mmm-yy")&" – "&TEXT(MAX(_xlfn.MAXIFS(Holdings!$J$6:$J$205,Holdings!$H$6:$H$205,$B17),_xlfn.MAXIFS(Holdings!$K$6:$K$205,Holdings!$H$6:$H$205,$B17)),"mmm-yy")) -> Mar-24 – Mar-24 | D17: =SUMIFS(Holdings!$M$6:$M$205,Holdings!$H$6:$H$205,$B17)/Divisor -> 5 | E17: =SUMIFS(Holdings!$R$6:$R$205,Holdings!$H$6:$H$205,$B17)/Divisor -> 5.062 | F17: =IF(N($E$31)=0,"",E17/$E$31) -> 0.036555459 | G17: =IF(N($E$15)=0,"",E17/$E$15) -> 0.37233773 | I17: =SUMIFS(Holdings!$U$6:$U$205,Holdings!$H$6:$H$205,$B17)/Divisor -> 0.43 | K17: =(SUMIFS(Holdings!$V$6:$V$205,Holdings!$H$6:$H$205,$B17)+SUMIFS(Holdings!$S$6:$S$205,Holdings!$H$6:$H$205,$B17))/Divisor -> 0.062 | M17: =SUMIFS(Holdings!$S$6:$S$205,Holdings!$H$6:$H$205,$B17)/Divisor -> 0.062 | O17: =IF(N(D17)=0,"",M17/D17) -> 0.0124 | P17: =IF(SUMIFS(Holdings!$AQ$6:$AQ$205,Holdings!$H$6:$H$205,$B17)=0,"",SUMIFS(Holdings!$AP$6:$AP$205,Holdings!$H$6:$H$205,$B17)/SUMIFS(Holdings!$AQ$6:$AQ$205,Holdings!$H$6:$H$205,$B17)) -> 0.182 | R17: =IF(SUMIFS(Holdings!$AN$6:$AN$205,Holdings!$H$6:$H$205,$B17)=0,"",SUMIFS(Holdings!$AM$6:$AM$205,Holdings!$H$6:$H$205,$B17)/SUMIFS(Holdings!$AN$6:$AN$205,Holdings!$H$6:$H$205,$B17)) -> 0.089 | S17: =IF(SUMIFS(Holdings!$AN$6:$AN$205,Holdings!$H$6:$H$205,$B17)=0,"",SUMIFS(Holdings!$AO$6:$AO$205,Holdings!$H$6:$H$205,$B17)/SUMIFS(Holdings!$AN$6:$AN$205,Holdings!$H$6:$H$205,$B17)) -> 0.076 | T17: =IF(N(E17)=0,"",SUMIFS(Holdings!$AN$6:$AN$205,Holdings!$H$6:$H$205,$B17)/Divisor/E17) -> 1
B18: =Lists!$D$15 -> AIF Cat II – Private Credit | C18: =IF(COUNTIFS(Holdings!$H$6:$H$205,$B18,Holdings!$J$6:$J$205,">0")=0,"",TEXT(_xlfn.MINIFS(Holdings!$J$6:$J$205,Holdings!$H$6:$H$205,$B18),"mmm-yy")&" – "&TEXT(MAX(_xlfn.MAXIFS(Holdings!$J$6:$J$205,Holdings!$H$6:$H$205,$B18),_xlfn.MAXIFS(Holdings!$K$6:$K$205,Holdings!$H$6:$H$205,$B18)),"mmm-yy")) -> Jan-26 – May-26 | D18: =SUMIFS(Holdings!$M$6:$M$205,Holdings!$H$6:$H$205,$B18)/Divisor -> 1 | E18: =SUMIFS(Holdings!$R$6:$R$205,Holdings!$H$6:$H$205,$B18)/Divisor -> 1.0382 | F18: =IF(N($E$31)=0,"",E18/$E$31) -> 0.0074974076 | G18: =IF(N($E$15)=0,"",E18/$E$15) -> 0.076365278 | I18: =SUMIFS(Holdings!$U$6:$U$205,Holdings!$H$6:$H$205,$B18)/Divisor -> 0 | K18: =(SUMIFS(Holdings!$V$6:$V$205,Holdings!$H$6:$H$205,$B18)+SUMIFS(Holdings!$S$6:$S$205,Holdings!$H$6:$H$205,$B18))/Divisor -> 0.0382 | M18: =SUMIFS(Holdings!$S$6:$S$205,Holdings!$H$6:$H$205,$B18)/Divisor -> 0.0382 | O18: =IF(N(D18)=0,"",M18/D18) -> 0.0382 | P18: =IF(SUMIFS(Holdings!$AQ$6:$AQ$205,Holdings!$H$6:$H$205,$B18)=0,"",SUMIFS(Holdings!$AP$6:$AP$205,Holdings!$H$6:$H$205,$B18)/SUMIFS(Holdings!$AQ$6:$AQ$205,Holdings!$H$6:$H$205,$B18)) -> 0.031 | R18: =IF(SUMIFS(Holdings!$AN$6:$AN$205,Holdings!$H$6:$H$205,$B18)=0,"",SUMIFS(Holdings!$AM$6:$AM$205,Holdings!$H$6:$H$205,$B18)/SUMIFS(Holdings!$AN$6:$AN$205,Holdings!$H$6:$H$205,$B18)) | S18: =IF(SUMIFS(Holdings!$AN$6:$AN$205,Holdings!$H$6:$H$205,$B18)=0,"",SUMIFS(Holdings!$AO$6:$AO$205,Holdings!$H$6:$H$205,$B18)/SUMIFS(Holdings!$AN$6:$AN$205,Holdings!$H$6:$H$205,$B18)) | T18: =IF(N(E18)=0,"",SUMIFS(Holdings!$AN$6:$AN$205,Holdings!$H$6:$H$205,$B18)/Divisor/E18) -> 0
B19: =Lists!$D$16 -> Structured Product / MLD | C19: =IF(COUNTIFS(Holdings!$H$6:$H$205,$B19,Holdings!$J$6:$J$205,">0")=0,"",TEXT(_xlfn.MINIFS(Holdings!$J$6:$J$205,Holdings!$H$6:$H$205,$B19),"mmm-yy")&" – "&TEXT(MAX(_xlfn.MAXIFS(Holdings!$J$6:$J$205,Holdings!$H$6:$H$205,$B19),_xlfn.MAXIFS(Holdings!$K$6:$K$205,Holdings!$H$6:$H$205,$B19)),"mmm-yy")) | D19: =SUMIFS(Holdings!$M$6:$M$205,Holdings!$H$6:$H$205,$B19)/Divisor -> 0 | E19: =SUMIFS(Holdings!$R$6:$R$205,Holdings!$H$6:$H$205,$B19)/Divisor -> 0 | F19: =IF(N($E$31)=0,"",E19/$E$31) -> 0 | G19: =IF(N($E$15)=0,"",E19/$E$15) -> 0 | I19: =SUMIFS(Holdings!$U$6:$U$205,Holdings!$H$6:$H$205,$B19)/Divisor -> 0 | K19: =(SUMIFS(Holdings!$V$6:$V$205,Holdings!$H$6:$H$205,$B19)+SUMIFS(Holdings!$S$6:$S$205,Holdings!$H$6:$H$205,$B19))/Divisor -> 0 | M19: =SUMIFS(Holdings!$S$6:$S$205,Holdings!$H$6:$H$205,$B19)/Divisor -> 0 | O19: =IF(N(D19)=0,"",M19/D19) | P19: =IF(SUMIFS(Holdings!$AQ$6:$AQ$205,Holdings!$H$6:$H$205,$B19)=0,"",SUMIFS(Holdings!$AP$6:$AP$205,Holdings!$H$6:$H$205,$B19)/SUMIFS(Holdings!$AQ$6:$AQ$205,Holdings!$H$6:$H$205,$B19)) | R19: =IF(SUMIFS(Holdings!$AN$6:$AN$205,Holdings!$H$6:$H$205,$B19)=0,"",SUMIFS(Holdings!$AM$6:$AM$205,Holdings!$H$6:$H$205,$B19)/SUMIFS(Holdings!$AN$6:$AN$205,Holdings!$H$6:$H$205,$B19)) | S19: =IF(SUMIFS(Holdings!$AN$6:$AN$205,Holdings!$H$6:$H$205,$B19)=0,"",SUMIFS(Holdings!$AO$6:$AO$205,Holdings!$H$6:$H$205,$B19)/SUMIFS(Holdings!$AN$6:$AN$205,Holdings!$H$6:$H$205,$B19)) | T19: =IF(N(E19)=0,"",SUMIFS(Holdings!$AN$6:$AN$205,Holdings!$H$6:$H$205,$B19)/Divisor/E19)
B20: =Lists!$A$8 -> Cash | C20: =IF(COUNTIFS(Holdings!$G$6:$G$205,$B20,Holdings!$J$6:$J$205,">0")=0,"",TEXT(_xlfn.MINIFS(Holdings!$J$6:$J$205,Holdings!$G$6:$G$205,$B20),"mmm-yy")&" – "&TEXT(MAX(_xlfn.MAXIFS(Holdings!$J$6:$J$205,Holdings!$G$6:$G$205,$B20),_xlfn.MAXIFS(Holdings!$K$6:$K$205,Holdings!$G$6:$G$205,$B20)),"mmm-yy")) -> Dec-25 – Jun-26 | D20: =SUMIFS(Holdings!$M$6:$M$205,Holdings!$G$6:$G$205,$B20)/Divisor -> 17.4556 | E20: =SUMIFS(Holdings!$R$6:$R$205,Holdings!$G$6:$G$205,$B20)/Divisor -> 17.741647 | F20: =IF(N($E$31)=0,"",E20/$E$31) -> 0.12812209 | I20: =SUMIFS(Holdings!$U$6:$U$205,Holdings!$G$6:$G$205,$B20)/Divisor -> 0.0185 | K20: =(SUMIFS(Holdings!$V$6:$V$205,Holdings!$G$6:$G$205,$B20)+SUMIFS(Holdings!$S$6:$S$205,Holdings!$G$6:$G$205,$B20))/Divisor -> 0.28604696 | M20: =SUMIFS(Holdings!$S$6:$S$205,Holdings!$G$6:$G$205,$B20)/Divisor -> 0.28604696 | O20: =IF(N(D20)=0,"",M20/D20) -> 0.016387117 | P20: =IF(SUMIFS(Holdings!$AQ$6:$AQ$205,Holdings!$G$6:$G$205,$B20)=0,"",SUMIFS(Holdings!$AP$6:$AP$205,Holdings!$G$6:$G$205,$B20)/SUMIFS(Holdings!$AQ$6:$AQ$205,Holdings!$G$6:$G$205,$B20)) -> 0.021983341 | R20: =IF(SUMIFS(Holdings!$AN$6:$AN$205,Holdings!$G$6:$G$205,$B20)=0,"",SUMIFS(Holdings!$AM$6:$AM$205,Holdings!$G$6:$G$205,$B20)/SUMIFS(Holdings!$AN$6:$AN$205,Holdings!$G$6:$G$205,$B20)) | S20: =IF(SUMIFS(Holdings!$AN$6:$AN$205,Holdings!$G$6:$G$205,$B20)=0,"",SUMIFS(Holdings!$AO$6:$AO$205,Holdings!$G$6:$G$205,$B20)/SUMIFS(Holdings!$AN$6:$AN$205,Holdings!$G$6:$G$205,$B20)) | T20: =IF(N(E20)=0,"",SUMIFS(Holdings!$AN$6:$AN$205,Holdings!$G$6:$G$205,$B20)/Divisor/E20) -> 0
B21: =Lists!$D$17 -> Liquid / Overnight Fund | C21: =IF(COUNTIFS(Holdings!$H$6:$H$205,$B21,Holdings!$J$6:$J$205,">0")=0,"",TEXT(_xlfn.MINIFS(Holdings!$J$6:$J$205,Holdings!$H$6:$H$205,$B21),"mmm-yy")&" – "&TEXT(MAX(_xlfn.MAXIFS(Holdings!$J$6:$J$205,Holdings!$H$6:$H$205,$B21),_xlfn.MAXIFS(Holdings!$K$6:$K$205,Holdings!$H$6:$H$205,$B21)),"mmm-yy")) -> Jan-26 – Jun-26 | D21: =SUMIFS(Holdings!$M$6:$M$205,Holdings!$H$6:$H$205,$B21)/Divisor -> 7.895 | E21: =SUMIFS(Holdings!$R$6:$R$205,Holdings!$H$6:$H$205,$B21)/Divisor -> 7.999143 | F21: =IF(N($E$31)=0,"",E21/$E$31) -> 0.057766168 | G21: =IF(N($E$20)=0,"",E21/$E$20) -> 0.45086812 | I21: =SUMIFS(Holdings!$U$6:$U$205,Holdings!$H$6:$H$205,$B21)/Divisor -> 0 | K21: =(SUMIFS(Holdings!$V$6:$V$205,Holdings!$H$6:$H$205,$B21)+SUMIFS(Holdings!$S$6:$S$205,Holdings!$H$6:$H$205,$B21))/Divisor -> 0.10414296 | M21: =SUMIFS(Holdings!$S$6:$S$205,Holdings!$H$6:$H$205,$B21)/Divisor -> 0.10414296 | O21: =IF(N(D21)=0,"",M21/D21) -> 0.013191003 | P21: =IF(SUMIFS(Holdings!$AQ$6:$AQ$205,Holdings!$H$6:$H$205,$B21)=0,"",SUMIFS(Holdings!$AP$6:$AP$205,Holdings!$H$6:$H$205,$B21)/SUMIFS(Holdings!$AQ$6:$AQ$205,Holdings!$H$6:$H$205,$B21)) -> 0.013868271 | R21: =IF(SUMIFS(Holdings!$AN$6:$AN$205,Holdings!$H$6:$H$205,$B21)=0,"",SUMIFS(Holdings!$AM$6:$AM$205,Holdings!$H$6:$H$205,$B21)/SUMIFS(Holdings!$AN$6:$AN$205,Holdings!$H$6:$H$205,$B21)) | S21: =IF(SUMIFS(Holdings!$AN$6:$AN$205,Holdings!$H$6:$H$205,$B21)=0,"",SUMIFS(Holdings!$AO$6:$AO$205,Holdings!$H$6:$H$205,$B21)/SUMIFS(Holdings!$AN$6:$AN$205,Holdings!$H$6:$H$205,$B21)) | T21: =IF(N(E21)=0,"",SUMIFS(Holdings!$AN$6:$AN$205,Holdings!$H$6:$H$205,$B21)/Divisor/E21) -> 0
B22: =Lists!$D$18 -> Arbitrage Fund | C22: =IF(COUNTIFS(Holdings!$H$6:$H$205,$B22,Holdings!$J$6:$J$205,">0")=0,"",TEXT(_xlfn.MINIFS(Holdings!$J$6:$J$205,Holdings!$H$6:$H$205,$B22),"mmm-yy")&" – "&TEXT(MAX(_xlfn.MAXIFS(Holdings!$J$6:$J$205,Holdings!$H$6:$H$205,$B22),_xlfn.MAXIFS(Holdings!$K$6:$K$205,Holdings!$H$6:$H$205,$B22)),"mmm-yy")) -> Dec-25 – Jun-26 | D22: =SUMIFS(Holdings!$M$6:$M$205,Holdings!$H$6:$H$205,$B22)/Divisor -> 5.8156 | E22: =SUMIFS(Holdings!$R$6:$R$205,Holdings!$H$6:$H$205,$B22)/Divisor -> 5.997504 | F22: =IF(N($E$31)=0,"",E22/$E$31) -> 0.043311243 | G22: =IF(N($E$20)=0,"",E22/$E$20) -> 0.33804663 | I22: =SUMIFS(Holdings!$U$6:$U$205,Holdings!$H$6:$H$205,$B22)/Divisor -> 0 | K22: =(SUMIFS(Holdings!$V$6:$V$205,Holdings!$H$6:$H$205,$B22)+SUMIFS(Holdings!$S$6:$S$205,Holdings!$H$6:$H$205,$B22))/Divisor -> 0.181904 | M22: =SUMIFS(Holdings!$S$6:$S$205,Holdings!$H$6:$H$205,$B22)/Divisor -> 0.181904 | O22: =IF(N(D22)=0,"",M22/D22) -> 0.03127863 | P22: =IF(SUMIFS(Holdings!$AQ$6:$AQ$205,Holdings!$H$6:$H$205,$B22)=0,"",SUMIFS(Holdings!$AP$6:$AP$205,Holdings!$H$6:$H$205,$B22)/SUMIFS(Holdings!$AQ$6:$AQ$205,Holdings!$H$6:$H$205,$B22)) -> 0.033 | R22: =IF(SUMIFS(Holdings!$AN$6:$AN$205,Holdings!$H$6:$H$205,$B22)=0,"",SUMIFS(Holdings!$AM$6:$AM$205,Holdings!$H$6:$H$205,$B22)/SUMIFS(Holdings!$AN$6:$AN$205,Holdings!$H$6:$H$205,$B22)) | S22: =IF(SUMIFS(Holdings!$AN$6:$AN$205,Holdings!$H$6:$H$205,$B22)=0,"",SUMIFS(Holdings!$AO$6:$AO$205,Holdings!$H$6:$H$205,$B22)/SUMIFS(Holdings!$AN$6:$AN$205,Holdings!$H$6:$H$205,$B22)) | T22: =IF(N(E22)=0,"",SUMIFS(Holdings!$AN$6:$AN$205,Holdings!$H$6:$H$205,$B22)/Divisor/E22) -> 0
B23: =Lists!$D$19 -> Bank / Cash Balance | C23: =IF(COUNTIFS(Holdings!$H$6:$H$205,$B23,Holdings!$J$6:$J$205,">0")=0,"",TEXT(_xlfn.MINIFS(Holdings!$J$6:$J$205,Holdings!$H$6:$H$205,$B23),"mmm-yy")&" – "&TEXT(MAX(_xlfn.MAXIFS(Holdings!$J$6:$J$205,Holdings!$H$6:$H$205,$B23),_xlfn.MAXIFS(Holdings!$K$6:$K$205,Holdings!$H$6:$H$205,$B23)),"mmm-yy")) | D23: =SUMIFS(Holdings!$M$6:$M$205,Holdings!$H$6:$H$205,$B23)/Divisor -> 3.745 | E23: =SUMIFS(Holdings!$R$6:$R$205,Holdings!$H$6:$H$205,$B23)/Divisor -> 3.745 | F23: =IF(N($E$31)=0,"",E23/$E$31) -> 0.027044685 | G23: =IF(N($E$20)=0,"",E23/$E$20) -> 0.21108525 | I23: =SUMIFS(Holdings!$U$6:$U$205,Holdings!$H$6:$H$205,$B23)/Divisor -> 0.0185 | K23: =(SUMIFS(Holdings!$V$6:$V$205,Holdings!$H$6:$H$205,$B23)+SUMIFS(Holdings!$S$6:$S$205,Holdings!$H$6:$H$205,$B23))/Divisor -> 0 | M23: =SUMIFS(Holdings!$S$6:$S$205,Holdings!$H$6:$H$205,$B23)/Divisor -> 0 | O23: =IF(N(D23)=0,"",M23/D23) -> 0 | P23: =IF(SUMIFS(Holdings!$AQ$6:$AQ$205,Holdings!$H$6:$H$205,$B23)=0,"",SUMIFS(Holdings!$AP$6:$AP$205,Holdings!$H$6:$H$205,$B23)/SUMIFS(Holdings!$AQ$6:$AQ$205,Holdings!$H$6:$H$205,$B23)) | R23: =IF(SUMIFS(Holdings!$AN$6:$AN$205,Holdings!$H$6:$H$205,$B23)=0,"",SUMIFS(Holdings!$AM$6:$AM$205,Holdings!$H$6:$H$205,$B23)/SUMIFS(Holdings!$AN$6:$AN$205,Holdings!$H$6:$H$205,$B23)) | S23: =IF(SUMIFS(Holdings!$AN$6:$AN$205,Holdings!$H$6:$H$205,$B23)=0,"",SUMIFS(Holdings!$AO$6:$AO$205,Holdings!$H$6:$H$205,$B23)/SUMIFS(Holdings!$AN$6:$AN$205,Holdings!$H$6:$H$205,$B23)) | T23: =IF(N(E23)=0,"",SUMIFS(Holdings!$AN$6:$AN$205,Holdings!$H$6:$H$205,$B23)/Divisor/E23) -> 0
B24: =Lists!$A$9 -> Alternate | C24: =IF(COUNTIFS(Holdings!$G$6:$G$205,$B24,Holdings!$J$6:$J$205,">0")=0,"",TEXT(_xlfn.MINIFS(Holdings!$J$6:$J$205,Holdings!$G$6:$G$205,$B24),"mmm-yy")&" – "&TEXT(MAX(_xlfn.MAXIFS(Holdings!$J$6:$J$205,Holdings!$G$6:$G$205,$B24),_xlfn.MAXIFS(Holdings!$K$6:$K$205,Holdings!$G$6:$G$205,$B24)),"mmm-yy")) -> Sep-23 – Apr-26 | D24: =SUMIFS(Holdings!$M$6:$M$205,Holdings!$G$6:$G$205,$B24)/Divisor -> 20.06 | E24: =SUMIFS(Holdings!$R$6:$R$205,Holdings!$G$6:$G$205,$B24)/Divisor -> 22.78356 | F24: =IF(N($E$31)=0,"",E24/$E$31) -> 0.16453249 | I24: =SUMIFS(Holdings!$U$6:$U$205,Holdings!$G$6:$G$205,$B24)/Divisor -> 0.36 | K24: =(SUMIFS(Holdings!$V$6:$V$205,Holdings!$G$6:$G$205,$B24)+SUMIFS(Holdings!$S$6:$S$205,Holdings!$G$6:$G$205,$B24))/Divisor -> 2.93356 | M24: =SUMIFS(Holdings!$S$6:$S$205,Holdings!$G$6:$G$205,$B24)/Divisor -> 2.72356 | O24: =IF(N(D24)=0,"",M24/D24) -> 0.13577069 | P24: =IF(SUMIFS(Holdings!$AQ$6:$AQ$205,Holdings!$G$6:$G$205,$B24)=0,"",SUMIFS(Holdings!$AP$6:$AP$205,Holdings!$G$6:$G$205,$B24)/SUMIFS(Holdings!$AQ$6:$AQ$205,Holdings!$G$6:$G$205,$B24)) -> 0.23628412 | R24: =IF(SUMIFS(Holdings!$AN$6:$AN$205,Holdings!$G$6:$G$205,$B24)=0,"",SUMIFS(Holdings!$AM$6:$AM$205,Holdings!$G$6:$G$205,$B24)/SUMIFS(Holdings!$AN$6:$AN$205,Holdings!$G$6:$G$205,$B24)) -> 0.13638576 | S24: =IF(SUMIFS(Holdings!$AN$6:$AN$205,Holdings!$G$6:$G$205,$B24)=0,"",SUMIFS(Holdings!$AO$6:$AO$205,Holdings!$G$6:$G$205,$B24)/SUMIFS(Holdings!$AN$6:$AN$205,Holdings!$G$6:$G$205,$B24)) -> 0.11561472 | T24: =IF(N(E24)=0,"",SUMIFS(Holdings!$AN$6:$AN$205,Holdings!$G$6:$G$205,$B24)/Divisor/E24) -> 0.67365943
B25: =Lists!$D$20 -> Gold / Silver (ETF, SGB, FoF) | C25: =IF(COUNTIFS(Holdings!$H$6:$H$205,$B25,Holdings!$J$6:$J$205,">0")=0,"",TEXT(_xlfn.MINIFS(Holdings!$J$6:$J$205,Holdings!$H$6:$H$205,$B25),"mmm-yy")&" – "&TEXT(MAX(_xlfn.MAXIFS(Holdings!$J$6:$J$205,Holdings!$H$6:$H$205,$B25),_xlfn.MAXIFS(Holdings!$K$6:$K$205,Holdings!$H$6:$H$205,$B25)),"mmm-yy")) -> Feb-24 – Aug-25 | D25: =SUMIFS(Holdings!$M$6:$M$205,Holdings!$H$6:$H$205,$B25)/Divisor -> 3.96 | E25: =SUMIFS(Holdings!$R$6:$R$205,Holdings!$H$6:$H$205,$B25)/Divisor -> 4.76676 | F25: =IF(N($E$31)=0,"",E25/$E$31) -> 0.03442337 | G25: =IF(N($E$24)=0,"",E25/$E$24) -> 0.20921928 | I25: =SUMIFS(Holdings!$U$6:$U$205,Holdings!$H$6:$H$205,$B25)/Divisor -> 0 | K25: =(SUMIFS(Holdings!$V$6:$V$205,Holdings!$H$6:$H$205,$B25)+SUMIFS(Holdings!$S$6:$S$205,Holdings!$H$6:$H$205,$B25))/Divisor -> 0.80676 | M25: =SUMIFS(Holdings!$S$6:$S$205,Holdings!$H$6:$H$205,$B25)/Divisor -> 0.80676 | O25: =IF(N(D25)=0,"",M25/D25) -> 0.20372727 | P25: =IF(SUMIFS(Holdings!$AQ$6:$AQ$205,Holdings!$H$6:$H$205,$B25)=0,"",SUMIFS(Holdings!$AP$6:$AP$205,Holdings!$H$6:$H$205,$B25)/SUMIFS(Holdings!$AQ$6:$AQ$205,Holdings!$H$6:$H$205,$B25)) -> 0.20945455 | R25: =IF(SUMIFS(Holdings!$AN$6:$AN$205,Holdings!$H$6:$H$205,$B25)=0,"",SUMIFS(Holdings!$AM$6:$AM$205,Holdings!$H$6:$H$205,$B25)/SUMIFS(Holdings!$AN$6:$AN$205,Holdings!$H$6:$H$205,$B25)) -> 0.116 | S25: =IF(SUMIFS(Holdings!$AN$6:$AN$205,Holdings!$H$6:$H$205,$B25)=0,"",SUMIFS(Holdings!$AO$6:$AO$205,Holdings!$H$6:$H$205,$B25)/SUMIFS(Holdings!$AN$6:$AN$205,Holdings!$H$6:$H$205,$B25)) -> 0.123 | T25: =IF(N(E25)=0,"",SUMIFS(Holdings!$AN$6:$AN$205,Holdings!$H$6:$H$205,$B25)/Divisor/E25) -> 0.63597916
B26: =Lists!$D$21 -> REIT / InvIT | C26: =IF(COUNTIFS(Holdings!$H$6:$H$205,$B26,Holdings!$J$6:$J$205,">0")=0,"",TEXT(_xlfn.MINIFS(Holdings!$J$6:$J$205,Holdings!$H$6:$H$205,$B26),"mmm-yy")&" – "&TEXT(MAX(_xlfn.MAXIFS(Holdings!$J$6:$J$205,Holdings!$H$6:$H$205,$B26),_xlfn.MAXIFS(Holdings!$K$6:$K$205,Holdings!$H$6:$H$205,$B26)),"mmm-yy")) -> Oct-24 – Oct-24 | D26: =SUMIFS(Holdings!$M$6:$M$205,Holdings!$H$6:$H$205,$B26)/Divisor -> 4.4 | E26: =SUMIFS(Holdings!$R$6:$R$205,Holdings!$H$6:$H$205,$B26)/Divisor -> 4.728 | F26: =IF(N($E$31)=0,"",E26/$E$31) -> 0.034143463 | G26: =IF(N($E$24)=0,"",E26/$E$24) -> 0.20751805 | I26: =SUMIFS(Holdings!$U$6:$U$205,Holdings!$H$6:$H$205,$B26)/Divisor -> 0.36 | K26: =(SUMIFS(Holdings!$V$6:$V$205,Holdings!$H$6:$H$205,$B26)+SUMIFS(Holdings!$S$6:$S$205,Holdings!$H$6:$H$205,$B26))/Divisor -> 0.328 | M26: =SUMIFS(Holdings!$S$6:$S$205,Holdings!$H$6:$H$205,$B26)/Divisor -> 0.328 | O26: =IF(N(D26)=0,"",M26/D26) -> 0.074545455 | P26: =IF(SUMIFS(Holdings!$AQ$6:$AQ$205,Holdings!$H$6:$H$205,$B26)=0,"",SUMIFS(Holdings!$AP$6:$AP$205,Holdings!$H$6:$H$205,$B26)/SUMIFS(Holdings!$AQ$6:$AQ$205,Holdings!$H$6:$H$205,$B26)) -> 0.119 | R26: =IF(SUMIFS(Holdings!$AN$6:$AN$205,Holdings!$H$6:$H$205,$B26)=0,"",SUMIFS(Holdings!$AM$6:$AM$205,Holdings!$H$6:$H$205,$B26)/SUMIFS(Holdings!$AN$6:$AN$205,Holdings!$H$6:$H$205,$B26)) -> 0.126 | S26: =IF(SUMIFS(Holdings!$AN$6:$AN$205,Holdings!$H$6:$H$205,$B26)=0,"",SUMIFS(Holdings!$AO$6:$AO$205,Holdings!$H$6:$H$205,$B26)/SUMIFS(Holdings!$AN$6:$AN$205,Holdings!$H$6:$H$205,$B26)) -> 0.091 | T26: =IF(N(E26)=0,"",SUMIFS(Holdings!$AN$6:$AN$205,Holdings!$H$6:$H$205,$B26)/Divisor/E26) -> 1
B27: =Lists!$D$22 -> AIF Cat I / II – PE / VC Fund | C27: =IF(COUNTIFS(Holdings!$H$6:$H$205,$B27,Holdings!$J$6:$J$205,">0")=0,"",TEXT(_xlfn.MINIFS(Holdings!$J$6:$J$205,Holdings!$H$6:$H$205,$B27),"mmm-yy")&" – "&TEXT(MAX(_xlfn.MAXIFS(Holdings!$J$6:$J$205,Holdings!$H$6:$H$205,$B27),_xlfn.MAXIFS(Holdings!$K$6:$K$205,Holdings!$H$6:$H$205,$B27)),"mmm-yy")) -> Sep-23 – Apr-26 | D27: =SUMIFS(Holdings!$M$6:$M$205,Holdings!$H$6:$H$205,$B27)/Divisor -> 6 | E27: =SUMIFS(Holdings!$R$6:$R$205,Holdings!$H$6:$H$205,$B27)/Divisor -> 7.5888 | F27: =IF(N($E$31)=0,"",E27/$E$31) -> 0.054802858 | G27: =IF(N($E$24)=0,"",E27/$E$24) -> 0.33308228 | I27: =SUMIFS(Holdings!$U$6:$U$205,Holdings!$H$6:$H$205,$B27)/Divisor -> 0 | K27: =(SUMIFS(Holdings!$V$6:$V$205,Holdings!$H$6:$H$205,$B27)+SUMIFS(Holdings!$S$6:$S$205,Holdings!$H$6:$H$205,$B27))/Divisor -> 1.7988 | M27: =SUMIFS(Holdings!$S$6:$S$205,Holdings!$H$6:$H$205,$B27)/Divisor -> 1.5888 | O27: =IF(N(D27)=0,"",M27/D27) -> 0.2648 | P27: =IF(SUMIFS(Holdings!$AQ$6:$AQ$205,Holdings!$H$6:$H$205,$B27)=0,"",SUMIFS(Holdings!$AP$6:$AP$205,Holdings!$H$6:$H$205,$B27)/SUMIFS(Holdings!$AQ$6:$AQ$205,Holdings!$H$6:$H$205,$B27)) -> 0.34 | R27: =IF(SUMIFS(Holdings!$AN$6:$AN$205,Holdings!$H$6:$H$205,$B27)=0,"",SUMIFS(Holdings!$AM$6:$AM$205,Holdings!$H$6:$H$205,$B27)/SUMIFS(Holdings!$AN$6:$AN$205,Holdings!$H$6:$H$205,$B27)) -> 0.151 | S27: =IF(SUMIFS(Holdings!$AN$6:$AN$205,Holdings!$H$6:$H$205,$B27)=0,"",SUMIFS(Holdings!$AO$6:$AO$205,Holdings!$H$6:$H$205,$B27)/SUMIFS(Holdings!$AN$6:$AN$205,Holdings!$H$6:$H$205,$B27)) -> 0.128 | T27: =IF(N(E27)=0,"",SUMIFS(Holdings!$AN$6:$AN$205,Holdings!$H$6:$H$205,$B27)/Divisor/E27) -> 1
B28: =Lists!$D$23 -> Private Equity – Unlisted Shares | C28: =IF(COUNTIFS(Holdings!$H$6:$H$205,$B28,Holdings!$J$6:$J$205,">0")=0,"",TEXT(_xlfn.MINIFS(Holdings!$J$6:$J$205,Holdings!$H$6:$H$205,$B28),"mmm-yy")&" – "&TEXT(MAX(_xlfn.MAXIFS(Holdings!$J$6:$J$205,Holdings!$H$6:$H$205,$B28),_xlfn.MAXIFS(Holdings!$K$6:$K$205,Holdings!$H$6:$H$205,$B28)),"mmm-yy")) -> Aug-24 – Jan-26 | D28: =SUMIFS(Holdings!$M$6:$M$205,Holdings!$H$6:$H$205,$B28)/Divisor -> 2.5 | E28: =SUMIFS(Holdings!$R$6:$R$205,Holdings!$H$6:$H$205,$B28)/Divisor -> 2.5 | F28: =IF(N($E$31)=0,"",E28/$E$31) -> 0.018053861 | G28: =IF(N($E$24)=0,"",E28/$E$24) -> 0.10972824 | I28: =SUMIFS(Holdings!$U$6:$U$205,Holdings!$H$6:$H$205,$B28)/Divisor -> 0 | K28: =(SUMIFS(Holdings!$V$6:$V$205,Holdings!$H$6:$H$205,$B28)+SUMIFS(Holdings!$S$6:$S$205,Holdings!$H$6:$H$205,$B28))/Divisor -> 0 | M28: =SUMIFS(Holdings!$S$6:$S$205,Holdings!$H$6:$H$205,$B28)/Divisor -> 0 | O28: =IF(N(D28)=0,"",M28/D28) -> 0 | P28: =IF(SUMIFS(Holdings!$AQ$6:$AQ$205,Holdings!$H$6:$H$205,$B28)=0,"",SUMIFS(Holdings!$AP$6:$AP$205,Holdings!$H$6:$H$205,$B28)/SUMIFS(Holdings!$AQ$6:$AQ$205,Holdings!$H$6:$H$205,$B28)) | R28: =IF(SUMIFS(Holdings!$AN$6:$AN$205,Holdings!$H$6:$H$205,$B28)=0,"",SUMIFS(Holdings!$AM$6:$AM$205,Holdings!$H$6:$H$205,$B28)/SUMIFS(Holdings!$AN$6:$AN$205,Holdings!$H$6:$H$205,$B28)) | S28: =IF(SUMIFS(Holdings!$AN$6:$AN$205,Holdings!$H$6:$H$205,$B28)=0,"",SUMIFS(Holdings!$AO$6:$AO$205,Holdings!$H$6:$H$205,$B28)/SUMIFS(Holdings!$AN$6:$AN$205,Holdings!$H$6:$H$205,$B28)) | T28: =IF(N(E28)=0,"",SUMIFS(Holdings!$AN$6:$AN$205,Holdings!$H$6:$H$205,$B28)/Divisor/E28) -> 0
B29: =Lists!$D$24 -> Pre-IPO | C29: =IF(COUNTIFS(Holdings!$H$6:$H$205,$B29,Holdings!$J$6:$J$205,">0")=0,"",TEXT(_xlfn.MINIFS(Holdings!$J$6:$J$205,Holdings!$H$6:$H$205,$B29),"mmm-yy")&" – "&TEXT(MAX(_xlfn.MAXIFS(Holdings!$J$6:$J$205,Holdings!$H$6:$H$205,$B29),_xlfn.MAXIFS(Holdings!$K$6:$K$205,Holdings!$H$6:$H$205,$B29)),"mmm-yy")) -> Nov-25 – Nov-25 | D29: =SUMIFS(Holdings!$M$6:$M$205,Holdings!$H$6:$H$205,$B29)/Divisor -> 3.2 | E29: =SUMIFS(Holdings!$R$6:$R$205,Holdings!$H$6:$H$205,$B29)/Divisor -> 3.2 | F29: =IF(N($E$31)=0,"",E29/$E$31) -> 0.023108943 | G29: =IF(N($E$24)=0,"",E29/$E$24) -> 0.14045215 | I29: =SUMIFS(Holdings!$U$6:$U$205,Holdings!$H$6:$H$205,$B29)/Divisor -> 0 | K29: =(SUMIFS(Holdings!$V$6:$V$205,Holdings!$H$6:$H$205,$B29)+SUMIFS(Holdings!$S$6:$S$205,Holdings!$H$6:$H$205,$B29))/Divisor -> 0 | M29: =SUMIFS(Holdings!$S$6:$S$205,Holdings!$H$6:$H$205,$B29)/Divisor -> 0 | O29: =IF(N(D29)=0,"",M29/D29) -> 0 | P29: =IF(SUMIFS(Holdings!$AQ$6:$AQ$205,Holdings!$H$6:$H$205,$B29)=0,"",SUMIFS(Holdings!$AP$6:$AP$205,Holdings!$H$6:$H$205,$B29)/SUMIFS(Holdings!$AQ$6:$AQ$205,Holdings!$H$6:$H$205,$B29)) | R29: =IF(SUMIFS(Holdings!$AN$6:$AN$205,Holdings!$H$6:$H$205,$B29)=0,"",SUMIFS(Holdings!$AM$6:$AM$205,Holdings!$H$6:$H$205,$B29)/SUMIFS(Holdings!$AN$6:$AN$205,Holdings!$H$6:$H$205,$B29)) | S29: =IF(SUMIFS(Holdings!$AN$6:$AN$205,Holdings!$H$6:$H$205,$B29)=0,"",SUMIFS(Holdings!$AO$6:$AO$205,Holdings!$H$6:$H$205,$B29)/SUMIFS(Holdings!$AN$6:$AN$205,Holdings!$H$6:$H$205,$B29)) | T29: =IF(N(E29)=0,"",SUMIFS(Holdings!$AN$6:$AN$205,Holdings!$H$6:$H$205,$B29)/Divisor/E29) -> 0
B31: Total | C31: =IF(COUNT(Holdings!$J$6:$J$205)=0,"",TEXT(MIN(Holdings!$J$6:$J$205),"mmm-yy")&" – "&TEXT(MAX(MAX(Holdings!$J$6:$J$205),MAX(Holdings!$K$6:$K$205)),"mmm-yy")) -> Mar-16 – Jun-26 | D31: =SUM(Holdings!$M$6:$M$205)/Divisor -> 110.19353 | E31: =SUM(Holdings!$R$6:$R$205)/Divisor -> 138.47453 | F31: =N(F7)+N(F15)+N(F20)+N(F24) -> 1 | I31: =SUM(Holdings!$U$6:$U$205)/Divisor -> 1.2235 | K31: =(SUM(Holdings!$V$6:$V$205)+SUM(Holdings!$S$6:$S$205))/Divisor -> 32.890001 | M31: =SUM(Holdings!$S$6:$S$205)/Divisor -> 28.281001 | O31: =IF(N(D31)=0,"",M31/D31) -> 0.25664847 | P31: =IF(SUM(Holdings!$AQ$6:$AQ$205)=0,"",SUM(Holdings!$AP$6:$AP$205)/SUM(Holdings!$AQ$6:$AQ$205)) -> 0.3565445 | R31: =IF(SUM(Holdings!$AN$6:$AN$205)=0,"",SUM(Holdings!$AM$6:$AM$205)/SUM(Holdings!$AN$6:$AN$205)) -> 0.13698029 | S31: =IF(SUM(Holdings!$AN$6:$AN$205)=0,"",SUM(Holdings!$AO$6:$AO$205)/SUM(Holdings!$AN$6:$AN$205)) -> 0.1215454 | T31: =IF(N(E31)=0,"",SUM(Holdings!$AN$6:$AN$205)/Divisor/E31) -> 0.76705776
B33: Returns: a holding held under a year shows its absolute return; a year or more, the XIRR its statement reports. A category's XIRR is value-weighted across its holdings, so read it as indicative.
B34: Private equity and pre-IPO shares are shown at cost until a priced round or a listing, so they carry no gain. Cash balances carry no return.
B35: Blended index: the benchmark return over the holdings that report one — cost-weighted for the absolute return, value-weighted for the XIRR. 'Share of value covered' is the part of the row's value that has an XIRR.
B36: Gain including redeemed = gain on what is held + realised gain on exits (Holdings). Dividend / interest is what each statement reports as received.
B38: PRIVATE MARKET COMMITMENTS — AIFs and private deals with a drawdown (first 10 rows of the Commitments sheet; the total covers every row)
B39: Fund | C39: Entity | D39: Committed | E39: Called to date | F39: % called | G39: Paid to date | I39: Uncalled | K39: Called, not yet paid | M39: Distributions received | O39: Current value | P39: TVPI (x) | R39: DPI (x) | S39: Next call date | T39: Next call amount
B40: =IF(INDEX(Commitments!$A$6:$A$35,1)="","",INDEX(Commitments!$E$6:$E$35,1)&"") -> Fernhill Ventures Fund II – Class A | C40: =IF(INDEX(Commitments!$A$6:$A$35,1)="","",INDEX(Commitments!$D$6:$D$35,1)&"") -> Malhotra Family Trust | D40: =IF(INDEX(Commitments!$A$6:$A$35,1)="","",IF(INDEX(Commitments!$G$6:$G$35,1)="","",INDEX(Commitments!$G$6:$G$35,1)/Divisor)) -> 10 | E40: =IF(INDEX(Commitments!$A$6:$A$35,1)="","",IF(INDEX(Commitments!$H$6:$H$35,1)="","",INDEX(Commitments!$H$6:$H$35,1)/Divisor)) -> 6 | F40: =IF(INDEX(Commitments!$A$6:$A$35,1)="","",IF(INDEX(Commitments!$M$6:$M$35,1)="","",INDEX(Commitments!$M$6:$M$35,1))) -> 0.6 | G40: =IF(INDEX(Commitments!$A$6:$A$35,1)="","",IF(INDEX(Commitments!$I$6:$I$35,1)="","",INDEX(Commitments!$I$6:$I$35,1)/Divisor)) -> 6 | I40: =IF(INDEX(Commitments!$A$6:$A$35,1)="","",IF(INDEX(Commitments!$K$6:$K$35,1)="","",INDEX(Commitments!$K$6:$K$35,1)/Divisor)) -> 4 | K40: =IF(INDEX(Commitments!$A$6:$A$35,1)="","",IF(INDEX(Commitments!$L$6:$L$35,1)="","",INDEX(Commitments!$L$6:$L$35,1)/Divisor)) -> 0 | M40: =IF(INDEX(Commitments!$A$6:$A$35,1)="","",IF(INDEX(Commitments!$J$6:$J$35,1)="","",INDEX(Commitments!$J$6:$J$35,1)/Divisor)) -> 0.85 | O40: =IF(INDEX(Commitments!$A$6:$A$35,1)="","",IF(INDEX(Commitments!$N$6:$N$35,1)="","",INDEX(Commitments!$N$6:$N$35,1)/Divisor)) -> 7.5888 | P40: =IF(INDEX(Commitments!$A$6:$A$35,1)="","",IF(INDEX(Commitments!$O$6:$O$35,1)="","",INDEX(Commitments!$O$6:$O$35,1))) -> 1.4064667 | R40: =IF(INDEX(Commitments!$A$6:$A$35,1)="","",IF(INDEX(Commitments!$P$6:$P$35,1)="","",INDEX(Commitments!$P$6:$P$35,1))) -> 0.14166667 | S40: =IF(INDEX(Commitments!$A$6:$A$35,1)="","",IF(INDEX(Commitments!$Q$6:$Q$35,1)="","",INDEX(Commitments!$Q$6:$Q$35,1))) -> 46280 | T40: =IF(INDEX(Commitments!$A$6:$A$35,1)="","",IF(INDEX(Commitments!$R$6:$R$35,1)="","",INDEX(Commitments!$R$6:$R$35,1)/Divisor)) -> 1
B41: =IF(INDEX(Commitments!$A$6:$A$35,2)="","",INDEX(Commitments!$E$6:$E$35,2)&"") -> Quill Robotics Pvt Ltd – Series A CCPS | C41: =IF(INDEX(Commitments!$A$6:$A$35,2)="","",INDEX(Commitments!$D$6:$D$35,2)&"") -> Rajiv Malhotra | D41: =IF(INDEX(Commitments!$A$6:$A$35,2)="","",IF(INDEX(Commitments!$G$6:$G$35,2)="","",INDEX(Commitments!$G$6:$G$35,2)/Divisor)) -> 3 | E41: =IF(INDEX(Commitments!$A$6:$A$35,2)="","",IF(INDEX(Commitments!$H$6:$H$35,2)="","",INDEX(Commitments!$H$6:$H$35,2)/Divisor)) -> 2.5 | F41: =IF(INDEX(Commitments!$A$6:$A$35,2)="","",IF(INDEX(Commitments!$M$6:$M$35,2)="","",INDEX(Commitments!$M$6:$M$35,2))) -> 0.83333333 | G41: =IF(INDEX(Commitments!$A$6:$A$35,2)="","",IF(INDEX(Commitments!$I$6:$I$35,2)="","",INDEX(Commitments!$I$6:$I$35,2)/Divisor)) -> 2.5 | I41: =IF(INDEX(Commitments!$A$6:$A$35,2)="","",IF(INDEX(Commitments!$K$6:$K$35,2)="","",INDEX(Commitments!$K$6:$K$35,2)/Divisor)) -> 0.5 | K41: =IF(INDEX(Commitments!$A$6:$A$35,2)="","",IF(INDEX(Commitments!$L$6:$L$35,2)="","",INDEX(Commitments!$L$6:$L$35,2)/Divisor)) -> 0 | M41: =IF(INDEX(Commitments!$A$6:$A$35,2)="","",IF(INDEX(Commitments!$J$6:$J$35,2)="","",INDEX(Commitments!$J$6:$J$35,2)/Divisor)) -> 0 | O41: =IF(INDEX(Commitments!$A$6:$A$35,2)="","",IF(INDEX(Commitments!$N$6:$N$35,2)="","",INDEX(Commitments!$N$6:$N$35,2)/Divisor)) -> 2.5 | P41: =IF(INDEX(Commitments!$A$6:$A$35,2)="","",IF(INDEX(Commitments!$O$6:$O$35,2)="","",INDEX(Commitments!$O$6:$O$35,2))) -> 1 | R41: =IF(INDEX(Commitments!$A$6:$A$35,2)="","",IF(INDEX(Commitments!$P$6:$P$35,2)="","",INDEX(Commitments!$P$6:$P$35,2))) -> 0 | S41: =IF(INDEX(Commitments!$A$6:$A$35,2)="","",IF(INDEX(Commitments!$Q$6:$Q$35,2)="","",INDEX(Commitments!$Q$6:$Q$35,2))) -> 46305 | T41: =IF(INDEX(Commitments!$A$6:$A$35,2)="","",IF(INDEX(Commitments!$R$6:$R$35,2)="","",INDEX(Commitments!$R$6:$R$35,2)/Divisor)) -> 0.5
B42: =IF(INDEX(Commitments!$A$6:$A$35,3)="","",INDEX(Commitments!$E$6:$E$35,3)&"") -> Rangoli Foods Pvt Ltd – Equity | C42: =IF(INDEX(Commitments!$A$6:$A$35,3)="","",INDEX(Commitments!$D$6:$D$35,3)&"") -> Malhotra Holdings LLP | D42: =IF(INDEX(Commitments!$A$6:$A$35,3)="","",IF(INDEX(Commitments!$G$6:$G$35,3)="","",INDEX(Commitments!$G$6:$G$35,3)/Divisor)) -> 3.2 | E42: =IF(INDEX(Commitments!$A$6:$A$35,3)="","",IF(INDEX(Commitments!$H$6:$H$35,3)="","",INDEX(Commitments!$H$6:$H$35,3)/Divisor)) -> 3.2 | F42: =IF(INDEX(Commitments!$A$6:$A$35,3)="","",IF(INDEX(Commitments!$M$6:$M$35,3)="","",INDEX(Commitments!$M$6:$M$35,3))) -> 1 | G42: =IF(INDEX(Commitments!$A$6:$A$35,3)="","",IF(INDEX(Commitments!$I$6:$I$35,3)="","",INDEX(Commitments!$I$6:$I$35,3)/Divisor)) -> 3.2 | I42: =IF(INDEX(Commitments!$A$6:$A$35,3)="","",IF(INDEX(Commitments!$K$6:$K$35,3)="","",INDEX(Commitments!$K$6:$K$35,3)/Divisor)) -> 0 | K42: =IF(INDEX(Commitments!$A$6:$A$35,3)="","",IF(INDEX(Commitments!$L$6:$L$35,3)="","",INDEX(Commitments!$L$6:$L$35,3)/Divisor)) -> 0 | M42: =IF(INDEX(Commitments!$A$6:$A$35,3)="","",IF(INDEX(Commitments!$J$6:$J$35,3)="","",INDEX(Commitments!$J$6:$J$35,3)/Divisor)) -> 0 | O42: =IF(INDEX(Commitments!$A$6:$A$35,3)="","",IF(INDEX(Commitments!$N$6:$N$35,3)="","",INDEX(Commitments!$N$6:$N$35,3)/Divisor)) -> 3.2 | P42: =IF(INDEX(Commitments!$A$6:$A$35,3)="","",IF(INDEX(Commitments!$O$6:$O$35,3)="","",INDEX(Commitments!$O$6:$O$35,3))) -> 1 | R42: =IF(INDEX(Commitments!$A$6:$A$35,3)="","",IF(INDEX(Commitments!$P$6:$P$35,3)="","",INDEX(Commitments!$P$6:$P$35,3))) -> 0 | S42: =IF(INDEX(Commitments!$A$6:$A$35,3)="","",IF(INDEX(Commitments!$Q$6:$Q$35,3)="","",INDEX(Commitments!$Q$6:$Q$35,3))) | T42: =IF(INDEX(Commitments!$A$6:$A$35,3)="","",IF(INDEX(Commitments!$R$6:$R$35,3)="","",INDEX(Commitments!$R$6:$R$35,3)/Divisor))
B43: =IF(INDEX(Commitments!$A$6:$A$35,4)="","",INDEX(Commitments!$E$6:$E$35,4)&"") -> Sahyadri Private Credit Fund – Series I | C43: =IF(INDEX(Commitments!$A$6:$A$35,4)="","",INDEX(Commitments!$D$6:$D$35,4)&"") -> Malhotra Family Trust | D43: =IF(INDEX(Commitments!$A$6:$A$35,4)="","",IF(INDEX(Commitments!$G$6:$G$35,4)="","",INDEX(Commitments!$G$6:$G$35,4)/Divisor)) -> 5 | E43: =IF(INDEX(Commitments!$A$6:$A$35,4)="","",IF(INDEX(Commitments!$H$6:$H$35,4)="","",INDEX(Commitments!$H$6:$H$35,4)/Divisor)) -> 1.25 | F43: =IF(INDEX(Commitments!$A$6:$A$35,4)="","",IF(INDEX(Commitments!$M$6:$M$35,4)="","",INDEX(Commitments!$M$6:$M$35,4))) -> 0.25 | G43: =IF(INDEX(Commitments!$A$6:$A$35,4)="","",IF(INDEX(Commitments!$I$6:$I$35,4)="","",INDEX(Commitments!$I$6:$I$35,4)/Divisor)) -> 1 | I43: =IF(INDEX(Commitments!$A$6:$A$35,4)="","",IF(INDEX(Commitments!$K$6:$K$35,4)="","",INDEX(Commitments!$K$6:$K$35,4)/Divisor)) -> 3.75 | K43: =IF(INDEX(Commitments!$A$6:$A$35,4)="","",IF(INDEX(Commitments!$L$6:$L$35,4)="","",INDEX(Commitments!$L$6:$L$35,4)/Divisor)) -> 0.25 | M43: =IF(INDEX(Commitments!$A$6:$A$35,4)="","",IF(INDEX(Commitments!$J$6:$J$35,4)="","",INDEX(Commitments!$J$6:$J$35,4)/Divisor)) -> 0 | O43: =IF(INDEX(Commitments!$A$6:$A$35,4)="","",IF(INDEX(Commitments!$N$6:$N$35,4)="","",INDEX(Commitments!$N$6:$N$35,4)/Divisor)) -> 1.0382 | P43: =IF(INDEX(Commitments!$A$6:$A$35,4)="","",IF(INDEX(Commitments!$O$6:$O$35,4)="","",INDEX(Commitments!$O$6:$O$35,4))) -> 1.0382 | R43: =IF(INDEX(Commitments!$A$6:$A$35,4)="","",IF(INDEX(Commitments!$P$6:$P$35,4)="","",INDEX(Commitments!$P$6:$P$35,4))) -> 0 | S43: =IF(INDEX(Commitments!$A$6:$A$35,4)="","",IF(INDEX(Commitments!$Q$6:$Q$35,4)="","",INDEX(Commitments!$Q$6:$Q$35,4))) -> 46315 | T43: =IF(INDEX(Commitments!$A$6:$A$35,4)="","",IF(INDEX(Commitments!$R$6:$R$35,4)="","",INDEX(Commitments!$R$6:$R$35,4)/Divisor)) -> 0.5
B44: =IF(INDEX(Commitments!$A$6:$A$35,5)="","",INDEX(Commitments!$E$6:$E$35,5)&"") | C44: =IF(INDEX(Commitments!$A$6:$A$35,5)="","",INDEX(Commitments!$D$6:$D$35,5)&"") | D44: =IF(INDEX(Commitments!$A$6:$A$35,5)="","",IF(INDEX(Commitments!$G$6:$G$35,5)="","",INDEX(Commitments!$G$6:$G$35,5)/Divisor)) | E44: =IF(INDEX(Commitments!$A$6:$A$35,5)="","",IF(INDEX(Commitments!$H$6:$H$35,5)="","",INDEX(Commitments!$H$6:$H$35,5)/Divisor)) | F44: =IF(INDEX(Commitments!$A$6:$A$35,5)="","",IF(INDEX(Commitments!$M$6:$M$35,5)="","",INDEX(Commitments!$M$6:$M$35,5))) | G44: =IF(INDEX(Commitments!$A$6:$A$35,5)="","",IF(INDEX(Commitments!$I$6:$I$35,5)="","",INDEX(Commitments!$I$6:$I$35,5)/Divisor)) | I44: =IF(INDEX(Commitments!$A$6:$A$35,5)="","",IF(INDEX(Commitments!$K$6:$K$35,5)="","",INDEX(Commitments!$K$6:$K$35,5)/Divisor)) | K44: =IF(INDEX(Commitments!$A$6:$A$35,5)="","",IF(INDEX(Commitments!$L$6:$L$35,5)="","",INDEX(Commitments!$L$6:$L$35,5)/Divisor)) | M44: =IF(INDEX(Commitments!$A$6:$A$35,5)="","",IF(INDEX(Commitments!$J$6:$J$35,5)="","",INDEX(Commitments!$J$6:$J$35,5)/Divisor)) | O44: =IF(INDEX(Commitments!$A$6:$A$35,5)="","",IF(INDEX(Commitments!$N$6:$N$35,5)="","",INDEX(Commitments!$N$6:$N$35,5)/Divisor)) | P44: =IF(INDEX(Commitments!$A$6:$A$35,5)="","",IF(INDEX(Commitments!$O$6:$O$35,5)="","",INDEX(Commitments!$O$6:$O$35,5))) | R44: =IF(INDEX(Commitments!$A$6:$A$35,5)="","",IF(INDEX(Commitments!$P$6:$P$35,5)="","",INDEX(Commitments!$P$6:$P$35,5))) | S44: =IF(INDEX(Commitments!$A$6:$A$35,5)="","",IF(INDEX(Commitments!$Q$6:$Q$35,5)="","",INDEX(Commitments!$Q$6:$Q$35,5))) | T44: =IF(INDEX(Commitments!$A$6:$A$35,5)="","",IF(INDEX(Commitments!$R$6:$R$35,5)="","",INDEX(Commitments!$R$6:$R$35,5)/Divisor))
...

Sheet Basket Allocation
A1: ="Basket Allocation — "&ClientName -> Basket Allocation — Malhotra Family Office (DEMO) | R1: =HYPERLINK("#'Start Here'!A1","← Start Here") -> ← Start Here
A2: ="Figures in "&UnitLabel&" · market values as at "&TEXT(ValDate,"dd-mmm-yyyy")&" · each basket's value by asset class, against the family's target" -> Figures in ₹ Crore · market values as at 30-Jun-2026 · each basket's value by asset class, against the family's target
A3: DEMO DATA — illustrative only: a fictional family, fictional securities and figures.
B5: Basket | C5: Code | D5: Market value by asset class | H5: Basket total | J5: Actual allocation (%) | K5: Target allocation (%) | L5: Gap: actual − target (% points) | N5: Investment at cost | O5: Gain / (loss) on what is held | P5: Absolute return (%) | Q5: XIRR (%) | R5: Share of value with an XIRR
D6: =Lists!$A$6 -> Equity | E6: =Lists!$A$7 -> Debt | F6: =Lists!$A$8 -> Cash | G6: =Lists!$A$9 -> Alternate
B7: =Lists!$L$6 -> Stable Growth | C7: =Lists!$K$6 -> SG | D7: =SUMIFS(Holdings!$R$6:$R$205,Holdings!$I$6:$I$205,$C7,Holdings!$G$6:$G$205,D$6)/Divisor -> 57.876525 | E7: =SUMIFS(Holdings!$R$6:$R$205,Holdings!$I$6:$I$205,$C7,Holdings!$G$6:$G$205,E$6)/Divisor -> 13.595184 | F7: =SUMIFS(Holdings!$R$6:$R$205,Holdings!$I$6:$I$205,$C7,Holdings!$G$6:$G$205,F$6)/Divisor -> 0 | G7: =SUMIFS(Holdings!$R$6:$R$205,Holdings!$I$6:$I$205,$C7,Holdings!$G$6:$G$205,G$6)/Divisor -> 4.728 | H7: =SUMIFS(Holdings!$R$6:$R$205,Holdings!$I$6:$I$205,$C7)/Divisor -> 76.199709 | J7: =IF(N($H$11)=0,"",H7/$H$11) -> 0.5502796 | K7: 0.45 | L7: =IF(OR(J7="",K7=""),"",J7-K7) -> 0.1002796 | N7: =SUMIFS(Holdings!$M$6:$M$205,Holdings!$I$6:$I$205,$C7)/Divisor -> 58.4168 | O7: =SUMIFS(Holdings!$S$6:$S$205,Holdings!$I$6:$I$205,$C7)/Divisor -> 17.782909 | P7: =IF(N(N7)=0,"",O7/N7) -> 0.3044143 | Q7: =IF(SUMIFS(Holdings!$AN$6:$AN$205,Holdings!$I$6:$I$205,$C7)=0,"",SUMIFS(Holdings!$AM$6:$AM$205,Holdings!$I$6:$I$205,$C7)/SUMIFS(Holdings!$AN$6:$AN$205,Holdings!$I$6:$I$205,$C7)) -> 0.13130084 | R7: =IF(N(H7)=0,"",SUMIFS(Holdings!$AN$6:$AN$205,Holdings!$I$6:$I$205,$C7)/Divisor/H7) -> 0.98637528
B8: =Lists!$L$7 -> Entrepreneurial Growth | C8: =Lists!$K$7 -> EG | D8: =SUMIFS(Holdings!$R$6:$R$205,Holdings!$I$6:$I$205,$C8,Holdings!$G$6:$G$205,D$6)/Divisor -> 0 | E8: =SUMIFS(Holdings!$R$6:$R$205,Holdings!$I$6:$I$205,$C8,Holdings!$G$6:$G$205,E$6)/Divisor -> 0 | F8: =SUMIFS(Holdings!$R$6:$R$205,Holdings!$I$6:$I$205,$C8,Holdings!$G$6:$G$205,F$6)/Divisor -> 0 | G8: =SUMIFS(Holdings!$R$6:$R$205,Holdings!$I$6:$I$205,$C8,Holdings!$G$6:$G$205,G$6)/Divisor -> 13.2888 | H8: =SUMIFS(Holdings!$R$6:$R$205,Holdings!$I$6:$I$205,$C8)/Divisor -> 13.2888 | J8: =IF(N($H$11)=0,"",H8/$H$11) -> 0.095965662 | K8: 0.12 | L8: =IF(OR(J8="",K8=""),"",J8-K8) -> -0.024034338 | N8: =SUMIFS(Holdings!$M$6:$M$205,Holdings!$I$6:$I$205,$C8)/Divisor -> 11.7 | O8: =SUMIFS(Holdings!$S$6:$S$205,Holdings!$I$6:$I$205,$C8)/Divisor -> 1.5888 | P8: =IF(N(N8)=0,"",O8/N8) -> 0.13579487 | Q8: =IF(SUMIFS(Holdings!$AN$6:$AN$205,Holdings!$I$6:$I$205,$C8)=0,"",SUMIFS(Holdings!$AM$6:$AM$205,Holdings!$I$6:$I$205,$C8)/SUMIFS(Holdings!$AN$6:$AN$205,Holdings!$I$6:$I$205,$C8)) -> 0.151 | R8: =IF(N(H8)=0,"",SUMIFS(Holdings!$AN$6:$AN$205,Holdings!$I$6:$I$205,$C8)/Divisor/H8) -> 0.57106736
B9: =Lists!$L$8 -> Liquidity | C9: =Lists!$K$8 -> LQ | D9: =SUMIFS(Holdings!$R$6:$R$205,Holdings!$I$6:$I$205,$C9,Holdings!$G$6:$G$205,D$6)/Divisor -> 0 | E9: =SUMIFS(Holdings!$R$6:$R$205,Holdings!$I$6:$I$205,$C9,Holdings!$G$6:$G$205,E$6)/Divisor -> 0 | F9: =SUMIFS(Holdings!$R$6:$R$205,Holdings!$I$6:$I$205,$C9,Holdings!$G$6:$G$205,F$6)/Divisor -> 17.741647 | G9: =SUMIFS(Holdings!$R$6:$R$205,Holdings!$I$6:$I$205,$C9,Holdings!$G$6:$G$205,G$6)/Divisor -> 0 | H9: =SUMIFS(Holdings!$R$6:$R$205,Holdings!$I$6:$I$205,$C9)/Divisor -> 17.741647 | J9: =IF(N($H$11)=0,"",H9/$H$11) -> 0.12812209 | K9: 0.15 | L9: =IF(OR(J9="",K9=""),"",J9-K9) -> -0.021877905 | N9: =SUMIFS(Holdings!$M$6:$M$205,Holdings!$I$6:$I$205,$C9)/Divisor -> 17.4556 | O9: =SUMIFS(Holdings!$S$6:$S$205,Holdings!$I$6:$I$205,$C9)/Divisor -> 0.28604696 | P9: =IF(N(N9)=0,"",O9/N9) -> 0.016387117 | Q9: =IF(SUMIFS(Holdings!$AN$6:$AN$205,Holdings!$I$6:$I$205,$C9)=0,"",SUMIFS(Holdings!$AM$6:$AM$205,Holdings!$I$6:$I$205,$C9)/SUMIFS(Holdings!$AN$6:$AN$205,Holdings!$I$6:$I$205,$C9)) | R9: =IF(N(H9)=0,"",SUMIFS(Holdings!$AN$6:$AN$205,Holdings!$I$6:$I$205,$C9)/Divisor/H9) -> 0
